Workbook

Sheet ข้าราชการ
A1: รายละเอียดเงินเดือนข้าราชการ โรงพยาบาลสามโคก
A2: ประจำเดือนพฤศจิกายน 2568
A3: ที่ | B3: ชื่อ - นามสกุล | D3: รายรับ | N3: รายจ่าย
D4: ตำแหน่ง | E4: เงินเดือน | F4: เงินตำแหน่ง | G4: เงินเพิ่มพิเศษ ไม่ทำเวชปฏิบัติ | H4: ค่าตอบแทน พตส. | I4: ค่าตอบแทน ฉ.11 ตค.68 | J4: ค่าตอบแทนนอกเวลา ราชการ ตค.68 | K4: ค่าตอบแทนแพทย์ พย.68 | L4: ค่าการศึกษาบุตร | M4: ค่ารักษาพยาบาล | N4: ภาษี | O4: กบข. | P4: กยศ. | Q4: ฌกส. | R4: ออมสิน | S4: กรุงไทย | T4: ไฟฟ้า | U4: ประปา | V4: รับจริง
A8: 1 | B8: นายจตุพงษ์ | C8: จันทร์ทอง | D8: นายแพทย์ | G8: 200 | K8: 20 | S8: 10 | V8: =E8+F8+G8+H8+I8+J8+K8+L8+M8-N8-O8-P8-Q8-R8-S8-T8-U8 -> 210
A9: 2 | B9: น.ส.นิตยา | C9: สารีกิจ | D9: พ.วิชาชีพ | V9: =E9+F9+G9+H9+I9+J9+K9+L9+M9-N9-O9-P9-Q9-R9-S9-T9-U9 -> 0
A10: 3 | B10: น.ส.พนิดา | C10: พลนงค์ | D10: นักจัดการงานทั่วไป | V10: =E10+F10+G10+H10+I10+J10+K10+L10+M10-N10-O10-P10-Q10-R10-S10-T10-U10 -> 0
A11: 4 | B11: น.ส.รุ่งนภา | C11: พงษ์สีทอง | D11: จพง.ทันต | V11: =E11+F11+G11+H11+I11+J11+K11+L11+M11-N11-O11-P11-Q11-R11-S11-T11-U11 -> 0
A12: 5 | B12: นางระวิวรรรณ | C12: โพธิ์ทองคำ | D12: จพง.ทันต | V12: =E12+F12+G12+H12+I12+J12+K12+L12+M12-N12-O12-P12-Q12-R12-S12-T12-U12 -> 0
A13: 6 | B13: น.ส.ศิรินทรา | C13: บุญคำภา | D13: ทันตแพทย์ | V13: =E13+F13+G13+H13+I13+J13+K13+L13+M13-N13-O13-P13-Q13-R13-S13-T13-U13 -> 0
A14: 7 | B14: น.ส.พัชภาพร | C14: คุ้มเรือง | D14: จพง.ทันต | V14: =E14+F14+G14+H14+I14+J14+K14+L14+M14-N14-O14-P14-Q14-R14-S14-T14-U14 -> 0
A15: 8 | B15: นางนิติธร | C15: ศรียะพันธ์ | D15: ทันตแพทย์ | V15: =E15+F15+G15+H15+I15+J15+K15+L15+M15-N15-O15-P15-Q15-R15-S15-T15-U15 -> 0
A16: 9 | B16: นายรุจนพล | C16: อมรลักษณานนท์ | D16: ทันตแพทย์ | V16: =E16+F16+G16+H16+I16+J16+K16+L16+M16-N16-O16-P16-Q16-R16-S16-T16-U16 -> 0
A17: 10 | B17: น.ส.อัญพิชญ์ | C17: วาสะประเสริฐ | D17: ทันตแพทย์ | V17: =E17+F17+G17+H17+I17+J17+K17+L17+M17-N17-O17-P17-Q17-R17-S17-T17-U17 -> 0
A18: 11 | B18: น.ส.บังอร | C18: ศรีไตรภพ | D18: นายแพทย์ | V18: =E18+F18+G18+H18+I18+J18+K18+L18+M18-N18-O18-P18-Q18-R18-S18-T18-U18 -> 0
A19: 12 | B19: นางสิริพักตร์ | C19: สุขสอาด | D19: จพง.รังสี | V19: =E19+F19+G19+H19+I19+J19+K19+L19+M19-N19-O19-P19-Q19-R19-S19-T19-U19 -> 0
A20: 13 | B20: นางวิริยา | C20: มาตรา | D20: เภสัชกร | V20: =E20+F20+G20+H20+I20+J20+K20+L20+M20-N20-O20-P20-Q20-R20-S20-T20-U20 -> 0
... A24: 17 | B24: น.ส.พิรดา | C24: วงศ์ซื่อ | D24: เภสัชกร | V24: =E24+F24+G24+H24+I24+J24+K24+L24+M24-N24-O24-P24-Q24-R24-S24-T24-U24 -> 0
A25: ยอดยกไป | E25: =SUM(E8:E24) -> 0 | F25: =SUM(F8:F24) -> 0 | G25: =SUM(G8:G24) -> 200 | H25: =SUM(H8:H24) -> 0 | I25: =SUM(I8:I24) -> 0 | J25: =SUM(J8:J24) -> 0 | K25: =SUM(K8:K24) -> 20 | L25: =SUM(L8:L24) -> 0 | ... V25: =SUM(V8:V24) -> 210
A26: ยอดยกมา | E26: =E25 -> 0 | F26: =F25 -> 0 | G26: =G25 -> 200 | H26: =H25 -> 0 | I26: =I25 -> 0 | J26: =J25 -> 0 | K26: =K25 -> 20 | L26: =L25 -> 0 | ... V26: =V25 -> 210
A27: 18 | B27: นางจิตวรินทร์ | C27: สิทธิโท | D27: พ.วิชาชีพ | V27: =E27+F27+G27+H27+I27+J27+K27+L27+M27-N27-O27-P27-Q27-R27-S27-T27-U27 -> 0
A28: 19 | B28: นางศิริวรรณ | C28: ปิยะพันธ์ | D28: พ.วิชาชีพ | V28: =E28+F28+G28+H28+I28+J28+K28+L28+M28-N28-O28-P28-Q28-R28-S28-T28-U28 -> 0
A29: 20 | B29: นางวิภาวรรณ | C29: นิ่มเดช | D29: พ.วิชาชีพ | V29: =E29+F29+G29+H29+I29+J29+K29+L29+M29-N29-O29-P29-Q29-R29-S29-T29-U29 -> 0
A30: 21 | B30: นางภคณี | C30: ศรีโสภณ | D30: พ.วิชาชีพ | V30: =E30+F30+G30+H30+I30+J30+K30+L30+M30-N30-O30-P30-Q30-R30-S30-T30-U30 -> 0
A31: 22 | B31: นางกิตติยา | C31: คลับคล้าย | D31: พ.วิชาชีพ | V31: =E31+F31+G31+H31+I31+J31+K31+L31+M31-N31-O31-P31-Q31-R31-S31-T31-U31 -> 0
A32: 23 | B32: น.ส.อรอุมา | C32: เกิดภาษี | D32: พ.วิชาชีพ | V32: =E32+F32+G32+H32+I32+J32+K32+L32+M32-N32-O32-P32-Q32-R32-S32-T32-U32 -> 0
A33: 24 | B33: นางอรุณรัตน์ | C33: ภควัตชัย | D33: พ.วิชาชีพ | V33: =E33+F33+G33+H33+I33+J33+K33+L33+M33-N33-O33-P33-Q33-R33-S33-T33-U33 -> 0
A34: 25 | B34: น.ส.จีรวัจน์ | C34: ฤทธิรณ | D34: พ.วิชาชีพ | V34: =E34+F34+G34+H34+I34+J34+K34+L34+M34-N34-O34-P34-Q34-R34-S34-T34-U34 -> 0
A35: 26 | B35: น.ส.พจนา | C35: พวงธรรม | D35: พ.วิชาชีพ | V35: =E35+F35+G35+H35+I35+J35+K35+L35+M35-N35-O35-P35-Q35-R35-S35-T35-U35 -> 0
A36: 27 | B36: นางพรทิพย์ | C36: ธนเตชะสิน | D36: พ.วิชาชีพ | V36: =E36+F36+G36+H36+I36+J36+K36+L36+M36-N36-O36-P36-Q36-R36-S36-T36-U36 -> 0
A37: 28 | B37: นางวิภาพร | C37: มีทา | D37: พ.วิชาชีพ | V37: =E37+F37+G37+H37+I37+J37+K37+L37+M37-N37-O37-P37-Q37-R37-S37-T37-U37 -> 0
A38: 29 | B38: น.ส.ปาจรีย์ | C38: เยื่อปุย | D38: พ.วิชาชีพ | V38: =E38+F38+G38+H38+I38+J38+K38+L38+M38-N38-O38-P38-Q38-R38-S38-T38-U38 -> 0
... A42: 33 | B42: น.ส.สุดารัตน์ | C42: จั่นจำรูญ | D42: พ.วิชาชีพ | V42: =E42+F42+G42+H42+I42+J42+K42+L42+M42-N42-O42-P42-Q42-R42-S42-T42-U42 -> 0
A43: ยอดยกไป | E43: =SUM(E26:E42) -> 0 | F43: =SUM(F26:F42) -> 0 | G43: =SUM(G26:G42) -> 200 | H43: =SUM(H26:H42) -> 0 | I43: =SUM(I26:I42) -> 0 | J43: =SUM(J26:J42) -> 0 | K43: =SUM(K26:K42) -> 20 | L43: =SUM(L26:L42) -> 0 | ... V43: =SUM(V26:V42) -> 210
A44: ยอดยกมา | E44: =E43 -> 0 | F44: =F43 -> 0 | G44: =G43 -> 200 | H44: =H43 -> 0 | I44: =I43 -> 0 | J44: =J43 -> 0 | K44: =K43 -> 20 | L44: =L43 -> 0 | ... V44: =V43 -> 210
A45: 34 | B45: น.ส.ผกาพรรณ | C45: พรรณพลีวรรณ | D45: พ.วิชาชีพ | V45: =E45+F45+G45+H45+I45+J45+K45+L45+M45-N45-O45-P45-Q45-R45-S45-T45-U45 -> 0
A46: 35 | B46: น.ส.ปวีณ์สุดา | C46: จันทรประยงค์ | D46: พ.วิชาชีพ | V46: =E46+F46+G46+H46+I46+J46+K46+L46+M46-N46-O46-P46-Q46-R46-S46-T46-U46 -> 0
A47: 36 | B47: น.ส.รจนา | C47: สาสาร | D47: พ.วิชาชีพ | V47: =E47+F47+G47+H47+I47+J47+K47+L47+M47-N47-O47-P47-Q47-R47-S47-T47-U47 -> 0
A48: 37 | B48: น.ส.จิตรวดี | C48: วิโรจน์ | D48: พ.วิชาชีพ | V48: =E48+F48+G48+H48+I48+J48+K48+L48+M48-N48-O48-P48-Q48-R48-S48-T48-U48 -> 0
A49: 38 | B49: น.ส.ทิพาพร | C49: ดนตรีเสนาะ | D49: พ.วิชาชีพ | V49: =E49+F49+G49+H49+I49+J49+K49+L49+M49-N49-O49-P49-Q49-R49-S49-T49-U49 -> 0
...

Sheet ลจ.ประจำ
A1: รายละเอียดเงินเดือนค่าจ้างประจำ โรงพยาบาลสามโคก
A2: =[1]ข้าราชการ!A2 -> ประจำเดือนพฤศจิกายน 2568
A3: ที่ | B3: ชื่อ - นามสกุล | D3: รายรับ | N3: รายจ่าย
D4: ตำแหน่ง | E4: เงินเดือน | F4: เงินตำแหน่ง | G4: เงินเพิ่มพิเศษ ไม่ทำเวชปฏิบัติ | H4: ค่าตอบแทน พตส. | I4: ค่าตอบแทน ฉ.11 ตค.68 | J4: ค่าตอบแทนนอกเวลา ราชการ ตค.68 | K4: ตกเบิกเงินเดือน | L4: ค่าการศึกษาบุตร | M4: ค่ารักษาพยาบาล | N4: ภาษี | O4: กสจ. | P4: สหกรณ์ | Q4: ฌกส. | R4: ออมสิน | S4: กรุงไทย | T4: ไฟฟ้า | U4: ประปา | V4: รับจริง
A8: 1 | B8: นางวรรณา | C8: ถนอมงาม | D8: พนักงานพัสดุ | I8: 10 | V8: =E8+F8+G8+H8+I8+J8+K8+L8+M8-N8-O8-P8-Q8-R8-S8-T8-U8 -> 10
A23: รวมทั้งสิ้น | E23: =SUM(E8:E10) -> 0 | F23: =SUM(F8:F10) -> 0 | G23: =SUM(G8:G10) -> 0 | H23: =SUM(H8:H10) -> 0 | I23: =SUM(I8:I11) -> 10 | J23: =SUM(J8:J15) -> 0 | K23: =SUM(K8:K15) -> 0 | L23: =SUM(L8:L15) -> 0 | M23: =SUM(M8:M15) -> 0 | N23: =SUM(N8:N10) -> 0 | O23: =SUM(O8:O10) -> 0 | P23: =SUM(P8:P10) -> 0 | Q23: =SUM(Q8:Q10) -> 0 | R23: =SUM(R8:R10) -> 0 | T23: =SUM(T8:T10) -> 0 | U23: =SUM(U8:U10) -> 0 | V23: =SUM(V8:V16) -> 10

Sheet พนักงาน
A1: รายละเอียดเงินเดือนพนักงานราชการ โรงพยาบาลสามโคก
A2: =[1]ข้าราชการ!A2 -> ประจำเดือนพฤศจิกายน 2568
A3: ที่ | B3: ชื่อ - นามสกุล | D3: รายรับ | N3: รายจ่าย
D4: ตำแหน่ง | E4: เงินเดือน | F4: เงินตำแหน่ง | G4: เงินเพิ่มพิเศษไม่ทำเวชปฏิบัติ | H4: ค่าตอบแทน พตส. | I4: ค่าตอบแทน ฉ.11 ตค.68 | J4: ค่าตอบแทนนอกเวลา ราชการ ตค.68 | K4: ตกเบิกเงินเดือน | L4: ค่าการศึกษาบุตร | M4: ค่ารักษาพยาบาล | N4: ภาษี | O4: ปกส. | P4: สหกรณ์ | Q4: ฌกส. | R4: ออมสิน | S4: กยศ. | T4: ไฟฟ้า | U4: ประปา | V4: รับจริง
A8: 1 | B8: น.ส.สุมาลี | C8: เสือเพชร | D8: นวก.การเงินและบัญชี | I8: 2 | J8: 3 | V8: =E8+F8+G8+H8+I8+J8+K8+L8+M8-N8-O8-P8-Q8-R8-S8-T8-U8 -> 5
A9: 2 | B9: น.ส.พิทยาภรณ์ | C9: เจริญสุข | D9: แพทย์แผนไทย | V9: =E9+F9+G9+H9+I9+J9+K9+L9+M9-N9-O9-P9-Q9-R9-S9-T9-U9 -> 0
A10: 3 | B10: น.ส.ณัฐวินีย์ | C10: แสงภูติ | D10: เภสัชกร | V10: =E10+F10+G10+H10+I10+J10+K10+L10+M10-N10-O10-P10-Q10-R10-S10-T10-U10 -> 0
A11: 4 | B11: น.ส.อัญธิญาน์ | C11: พรชัยวุฒิพงษ์ | D11: นักวิชาการพัสดุ | V11: =E11+F11+G11+H11+I11+J11+K11+L11+M11-N11-O11-P11-Q11-R11-S11-T11-U11 -> 0
A24: รวมทั้งสิ้น | E24: =SUM(E8:E23) -> 0 | F24: =SUM(F8:F23) -> 0 | G24: =SUM(G8:G23) -> 0 | H24: =SUM(H8:H23) -> 0 | I24: =SUM(I8:I23) -> 2 | J24: =SUM(J8:J23) -> 3 | K24: =SUM(K8:K23) -> 0 | L24: =SUM(L8:L23) -> 0 | ... V24: =SUM(V8:V23) -> 5

Sheet พกส.
A1: รายละเอียดเงินเดือนพนักงานกระทรวงสาธารณสุข โรงพยาบาลสามโคก
A2: =[1]ข้าราชการ!A2 -> ประจำเดือนพฤศจิกายน 2568
A3: ที่ | B3: ชื่อ - นามสกุล | D3: รายรับ | N3: รายจ่าย
D4: ตำแหน่ง | E4: เงินเดือน | F4: เงินตำแหน่ง | G4: เงินเพิ่มพิเศษไม่ทำเวชปฏิบัติ | H4: ค่าตอบแทน พตส.พย.68 | I4: ค่าตอบแทน ฉ.11 ตค.68 | J4: ค่าตอบแทนนอกเวลา ราชการ ตค.68 | K4: ค่าตอบแทนพิเศษเต็มขั้น ตค.-พย.68 | L4: ตกเบิกเงินเดือน ตค.68 | M4: ค่ารักษาพยาบาล | N4: ปกส. | O4: สหกรณ์ | P4: ฌกส. | Q4: ออมสิน | R4: กสล.พกส. | S4: กรุงไทย | T4: กยศ. | U4: ไฟฟ้า | V4: ประปา | W4: รับจริง
A8: 1 | B8: น.ส.จรัสศรี | C8: แสนศรี | D8: พนักงานธุรการ | E8: 10 | L8: 3 | N8: 1 | O8: 1 | R8: 1 | W8: =E8+F8+G8+H8+I8+J8+K8+L8+M8-N8-O8-P8-Q8-R8-S8-T8-U8-V8 -> 10
A9: 2 | B9: น.ส.เบญจวรรณ | C9: สุขชูศรี | D9: พนง.ช่วยเหลือคนไข้ | E9: 10 | K9: 500 | P9: 1 | Q9: 2 | W9: =E9+F9+G9+H9+I9+J9+K9+L9+M9-N9-O9-P9-Q9-R9-S9-T9-U9-V9 -> 507
A10: 3 | B10: นายสัญญา | C10: แย้มดี | D10: พนง.ช่วยเหลือคนไข้ | E10: 10 | Q10: 2 | T10: 2 | U10: 1 | V10: 1 | W10: =E10+F10+G10+H10+I10+J10+K10+L10+M10-N10-O10-P10-Q10-R10-S10-T10-U10-V10 -> 4
A11: 4 | B11: น.ส.วันวิลัย | C11: เวฬุวนารักษ์ | D11: ผู้ช่วยทันตแพทย์ | W11: =E11+F11+G11+H11+I11+J11+K11+L11+M11-N11-O11-P11-Q11-R11-S11-T11-U11-V11 -> 0
A12: 5 | B12: น.ส.เรณุกา | C12: อุบลพงษ์ | D12: นักจัดการงานทั่วไป | W12: =E12+F12+G12+H12+I12+J12+K12+L12+M12-N12-O12-P12-Q12-R12-S12-T12-U12-V12 -> 0
A13: 6 | B13: น.ส.อมรรัตน์ | C13: บุตรเรือง | D13: นวก.การเงินและบัญชี | W13: =E13+F13+G13+H13+I13+J13+K13+L13+M13-N13-O13-P13-Q13-R13-S13-T13-U13-V13 -> 0
A14: 7 | B14: นายวีรชัย | C14: มงคลธง | D14: นวก.การเงินและบัญชี | W14: =E14+F14+G14+H14+I14+J14+K14+L14+M14-N14-O14-P14-Q14-R14-S14-T14-U14-V14 -> 0
A15: 8 | B15: นางสินีนาฎ | C15: เขียวระยับ | D15: นวก.การเงินและบัญชี | W15: =E15+F15+G15+H15+I15+J15+K15+L15+M15-N15-O15-P15-Q15-R15-S15-T15-U15-V15 -> 0
A16: 9 | B16: น.ส.วิราภรณ์ | C16: มงคลธง | D16: นวก.การเงินและบัญชี | W16: =E16+F16+G16+H16+I16+J16+K16+L16+M16-N16-O16-P16-Q16-R16-S16-T16-U16-V16 -> 0
A17: 10 | B17: น.ส.จิรวรรณ | C17: เยี่ยมจรรยา | D17: พนักงานประจำห้องยา | W17: =E17+F17+G17+H17+I17+J17+K17+L17+M17-N17-O17-P17-Q17-R17-S17-T17-U17-V17 -> 0
A18: 11 | B18: น.ส.วิลาวัณย์ | C18: คล้ายประสิทธิ์ | D18: พนง.ช่วยเหลือคนไข้ | W18: =E18+F18+G18+H18+I18+J18+K18+L18+M18-N18-O18-P18-Q18-R18-S18-T18-U18-V18 -> 0
A19: 12 | B19: น.ส.กิติยาพร | C19: โพธิ์ทอง | D19: พนง.ช่วยเหลือคนไข้ | W19: =E19+F19+G19+H19+I19+J19+K19+L19+M19-N19-O19-P19-Q19-R19-S19-T19-U19-V19 -> 0
A20: 13 | B20: น.ส.ธัญญารัตน์ | C20: เฉียดจะโป๊ะ | D20: พนง.ช่วยเหลือคนไข้ | W20: =E20+F20+G20+H20+I20+J20+K20+L20+M20-N20-O20-P20-Q20-R20-S20-T20-U20-V20 -> 0
A21: 14 | B21: นางนุชรา | C21: ชักชวน | D21: พนักงานประจำห้องยา | W21: =E21+F21+G21+H21+I21+J21+K21+L21+M21-N21-O21-P21-Q21-R21-S21-T21-U21-V21 -> 0
A22: 15 | B22: น.ส.วินา | C22: จันสด | D22: ผู้ช่วยทันตแพทย์ | W22: =E22+F22+G22+H22+I22+J22+K22+L22+M22-N22-O22-P22-Q22-R22-S22-T22-U22-V22 -> 0
... A24: 17 | B24: น.ส.กรรณิการ์ | C24: แสงมีคุณ | D24: พนักงานบริการ | W24: =E24+F24+G24+H24+I24+J24+K24+L24+M24-N24-O24-P24-Q24-R24-S24-T24-U24-V24 -> 0
A25: ยอดยกไป | E25: =SUM(E8:E24) -> 30 | F25: =SUM(F8:F24) -> 0 | G25: =SUM(G8:G24) -> 0 | H25: =SUM(H8:H24) -> 0 | I25: =SUM(I8:I24) -> 0 | J25: =SUM(J8:J24) -> 0 | K25: =SUM(K8:K24) -> 500 | L25: =SUM(L8:L24) -> 3 | ... W25: =SUM(W8:W24) -> 521
A26: ยอดยกมา | E26: =E25 -> 30 | F26: =F25 -> 0 | G26: =G25 -> 0 | H26: =H25 -> 0 | I26: =I25 -> 0 | J26: =J25 -> 0 | K26: =K25 -> 500 | L26: =L25 -> 3 | ... W26: =W25 -> 521
A27: 18 | B27: นายปรีดา | C27: การเก่ง | D27: พนง.ช่วยเหลือคนไข้ | W27: =E27+F27+G27+H27+I27+J27+K27+L27+M27-N27-O27-P27-Q27-R27-S27-T27-U27-V27 -> 0
A28: 19 | B28: น.ส.อรชนกพร | C28: อินทรขลิบ | D28: พนง.ช่วยเหลือคนไข้ | W28: =E28+F28+G28+H28+I28+J28+K28+L28+M28-N28-O28-P28-Q28-R28-S28-T28-U28-V28 -> 0
A29: 20 | B29: น.ส.อรญา | C29: แก้วตา | D29: นักวิชาการสาธารณสุข | W29: =E29+F29+G29+H29+I29+J29+K29+L29+M29-N29-O29-P29-Q29-R29-S29-T29-U29-V29 -> 0
A30: 21 | B30: น.ส.อัฉรา | C30: เรืองเพ็ชร์ | D30: พนักงานบริการ | W30: =E30+F30+G30+H30+I30+J30+K30+L30+M30-N30-O30-P30-Q30-R30-S30-T30-U30-V30 -> 0
A31: 22 | B31: น.ส.วชิรา | C31: โตสัจจะ | D31: นักกายภาพบำบัด | H31: 50 | J31: 5 | W31: =E31+F31+G31+H31+I31+J31+K31+L31+M31-N31-O31-P31-Q31-R31-S31-T31-U31-V31 -> 55
A32: 23 | B32: น.ส.รสิตา | C32: พรรณอรรถ | D32: นักจิตวิทยา | W32: =E32+F32+G32+H32+I32+J32+K32+L32+M32-N32-O32-P32-Q32-R32-S32-T32-U32-V32 -> 0
A33: 24 | B33: น.ส.ณัฐทิตา | C33: จันทรเกษมศุก | D33: นักวิชาการสาธารณสุข | W33: =E33+F33+G33+H33+I33+J33+K33+L33+M33-N33-O33-P33-Q33-R33-S33-T33-U33-V33 -> 0
A34: 25 | B34: นางศรัณย์ธร | C34: ครุฑสิน | D34: พนง.ช่วยเหลือคนไข้ | W34: =E34+F34+G34+H34+I34+J34+K34+L34+M34-N34-O34-P34-Q34-R34-S34-T34-U34-V34 -> 0
A35: 26 | B35: นายธรรมรัฐ | C35: บัวหลวง | D35: พนง.ช่วยเหลือคนไข้ | W35: =E35+F35+G35+H35+I35+J35+K35+L35+M35-N35-O35-P35-Q35-R35-S35-T35-U35-V35 -> 0
A36: 27 | B36: น.ส.วรรณิภา | C36: เบญมาตย์ | D36: แพทย์แผนไทย | W36: =E36+F36+G36+H36+I36+J36+K36+L36+M36-N36-O36-P36-Q36-R36-S36-T36-U36-V36 -> 0
A37: 28 | B37: น.ส.ฐิติมา | C37: ช้างกอน | D37: นักวิชาการสาธารณสุข | W37: =E37+F37+G37+H37+I37+J37+K37+L37+M37-N37-O37-P37-Q37-R37-S37-T37-U37-V37 -> 0
A38: 29 | B38: นายอัฐพล | C38: วงค์คำดี | D38: พนักงานขับรถยนต์ | W38: =E38+F38+G38+H38+I38+J38+K38+L38+M38-N38-O38-P38-Q38-R38-S38-T38-U38-V38 -> 0
A39: 30 | B39: น.ส.วรรณวิสา | C39: ธนะจักร์ | D39: พนง.ช่วยเหลือคนไข้ | W39: =E39+F39+G39+H39+I39+J39+K39+L39+M39-N39-O39-P39-Q39-R39-S39-T39-U39-V39 -> 0
A40: 31 | B40: น.ส.ศิริลักษณ์ | C40: ชมภูนุช | D40: พนง.ช่วยเหลือคนไข้ | W40: =E40+F40+G40+H40+I40+J40+K40+L40+M40-N40-O40-P40-Q40-R40-S40-T40-U40-V40 -> 0
A43: รวมทั้งสิ้น | E43: =SUM(E26:E40) -> 30 | F43: =SUM(F26:F40) -> 0 | G43: =SUM(G26:G40) -> 0 | H43: =SUM(H26:H40) -> 50 | I43: =SUM(I26:I40) -> 0 | J43: =SUM(J26:J40) -> 5 | K43: =SUM(K26:K40) -> 500 | L43: =SUM(L26:L40) -> 3 | ... V43: =SUM(V26:V40) -> 1 | W43: =SUM(W26:W42) -> 576

Sheet รายเดือน
A1: รายละเอียดเงินเดือนลูกจ้างชั่วคราวรายเดือน โรงพยาบาลสามโคก
A2: =[1]ข้าราชการ!A2 -> ประจำเดือนพฤศจิกายน 2568
A3: ที่ | B3: ชื่อ - นามสกุล | D3: รายรับ | N3: รายจ่าย
D4: ตำแหน่ง | E4: เงินเดือน | F4: เงินตำแหน่ง | G4: เงินเพิ่มพิเศษไม่ทำเวชปฏิบัติ | H4: ค่าตอบแทน พตส.พย.68 | I4: ค่าตอบแทน ฉ.11 ตค.68 | J4: ค่าตอบแทนนอกเวลา ราชการ ตค.68 | K4: ตกเบิกเงินเดือน | L4: ค่าการศึกษาบุตร | M4: ค่ารักษาพยาบาล | N4: ภาษี | O4: ปกส. | P4: สหกรณ์ | Q4: ฌกส. | R4: ออมสิน | S4: กยศ. | T4: ไฟฟ้า | U4: ประปา | V4: รับจริง
A8: 1 | B8: น.ส.ปพิชญา | C8: อังกีรัตน์ | D8: นักวิชาการสาธารณสุข | V8: =E8+F8+G8+H8+I8+J8+K8+L8+M8-N8-O8-P8-Q8-R8-S8-T8-U8 -> 0
A9: 2 | B9: น.ส.กัลยารัตน์ | C9: มหามนต์ | D9: นักวิชาการสาธารณสุข | V9: =E9+F9+G9+H9+I9+J9+K9+L9+M9-N9-O9-P9-Q9-R9-S9-T9-U9 -> 0
A10: 3 | B10: น.ส.วศิกา | C10: เจริญวุฒิกุล | D10: แพทย์แผนไทย | V10: =E10+F10+G10+H10+I10+J10+K10+L10+M10-N10-O10-P10-Q10-R10-S10-T10-U10 -> 0
A11: 4 | B11: น.ส.สุชาวดี | C11: อินกว่าง | D11: พยาบาลวิชาชีพ | V11: =E11+F11+G11+H11+I11+J11+K11+L11+M11-N11-O11-P11-Q11-R11-S11-T11-U11 -> 0
A12: 5 | B12: น.ส.สุภาดา | C12: อนันตะภูมิ | D12: พยาบาลวิชาชีพ | V12: =E12+F12+G12+H12+I12+J12+K12+L12+M12-N12-O12-P12-Q12-R12-S12-T12-U12 -> 0
A13: 6 | B13: น.ส.สุพัตรา | C13: พรมชาติ | D13: พยาบาลวิชาชีพ | V13: =E13+F13+G13+H13+I13+J13+K13+L13+M13-N13-O13-P13-Q13-R13-S13-T13-U13 -> 0
A14: 7 | B14: น.ส.มยุริญ | C14: ศรีมุกดา | D14: พยาบาลวิชาชีพ | V14: =E14+F14+G14+H14+I14+J14+K14+L14+M14-N14-O14-P14-Q14-R14-S14-T14-U14 -> 0
A15: 8 | B15: น.ส.ชลธิชา | C15: จำปาม่วง | D15: นักกายภาพบำบัด | V15: =E15+F15+G15+H15+I15+J15+K15+L15+M15-N15-O15-P15-Q15-R15-S15-T15-U15 -> 0
A16: 9 | B16: นายปุริม | C16: พิทยภูวไนย | D16: นักเทคนิคการแพทย์ | V16: =E16+F16+G16+H16+I16+J16+K16+L16+M16-N16-O16-P16-Q16-R16-S16-T16-U16 -> 0
A17: 10 | B17: น.ส.ปรารถนา | C17: ธรรมศักดิ์ชัย | D17: พนักงานประกอบอาหาร | V17: =E17+F17+G17+H17+I17+J17+K17+L17+M17-N17-O17-P17-Q17-R17-S17-T17-U17 -> 0
A18: 11 | B18: น.ส.พรปรียา | C18: สาไธสง | D18: พนักงานทั่วไป | V18: =E18+F18+G18+H18+I18+J18+K18+L18+M18-N18-O18-P18-Q18-R18-S18-T18-U18 -> 0
A19: 12 | B19: น.ส.บุษบง | C19: ดรบุรมย์ | D19: พนักงานบริการ | E19: 4 | O19: 1 | V19: =E19+F19+G19+H19+I19+J19+K19+L19+M19-N19-O19-P19-Q19-R19-S19-T19-U19 -> 3
A20: 13 | B20: น.ส.พรสิริ | C20: เวียงอินทร์ | D20: พนักงานเครื่องคอมพิวเตอร์ | V20: =E20+F20+G20+H20+I20+J20+K20+L20+M20-N20-O20-P20-Q20-R20-S20-T20-U20 -> 0
A21: 14 | B21: น.ส.นพมาศ | C21: คำสอน | D21: พนักงานช่วยเหลือคนไข้ | V21: =E21+F21+G21+H21+I21+J21+K21+L21+M21-N21-O21-P21-Q21-R21-S21-T21-U21 -> 0
A22: 15 | B22: น.ส.รัชตา | C22: พุ่มพยงค์ | D22: พนักงานช่วยเหลือคนไข้ | V22: =E22+F22+G22+H22+I22+J22+K22+L22+M22-N22-O22-P22-Q22-R22-S22-T22-U22 -> 0
A23: 16 | B23: น.ส.พรปวีณ์ | C23: ศรีโสภณ | D23: พนักงานบริการ | V23: =E23+F23+G23+H23+I23+J23+K23+L23+M23-N23-O23-P23-Q23-R23-S23-T23-U23 -> 0
A24: 17 | B24: นายศิรวิทย์ | C24: แก้วศรี | D24: พนักงานเปล | V24: =E24+F24+G24+H24+I24+J24+K24+L24+M24-N24-O24-P24-Q24-R24-S24-T24-U24 -> 0
A25: 18 | B25: นายบุญทำ | C25: จานทอง | D25: พนักงานเปล | V25: =E25+F25+G25+H25+I25+J25+K25+L25+M25-N25-O25-P25-Q25-R25-S25-T25-U25 -> 0
A26: รวมทั้งสิ้น | E26: =SUM(E8:E25) -> 4 | F26: =SUM(F8:F25) -> 0 | G26: =SUM(G8:G25) -> 0 | H26: =SUM(H8:H25) -> 0 | I26: =SUM(I8:I25) -> 0 | J26: =SUM(J8:J25) -> 0 | K26: =SUM(K8:K25) -> 0 | L26: =SUM(L9:L25) -> 0 | M26: =SUM(M9:M25) -> 0 | N26: =SUM(N9:N25) -> 0 | O26: =SUM(O8:O25) -> 1 | P26: =SUM(P8:P25) -> 0 | Q26: =SUM(Q8:Q25) -> 0 | R26: =SUM(R8:R25) -> 0 | S26: =SUM(S8:S25) -> 0 | T26: =SUM(T8:T25) -> 0 | U26: =SUM(U8:U25) -> 0 | V26: =SUM(V8:V25) -> 3

Sheet รายวัน
A1: รายละเอียดเงินเดือนลูกจ้างชั่วคราวรายวัน โรงพยาบาลสามโคก
A2: =[1]ข้าราชการ!A2 -> ประจำเดือนพฤศจิกายน 2568
A3: ที่ | B3: ชื่อ - นามสกุล | D3: รายรับ | N3: รายจ่าย
D4: ตำแหน่ง | E4: เงินเดือน | F4: เงินตำแหน่ง | G4: เงินเพิ่มพิเศษไม่ทำเวชปฏิบัติ | H4: ค่าตอบแทน พตส.พย.68 | I4: ค่าตอบแทน ฉ.11 ตค.68 | J4: ค่าตอบแทนนอกเวลา ราชการ ตค.68 | K4: ตกเบิกเงินเดือน | L4: ค่าการศึกษาบุตร | M4: ค่ารักษาพยาบาล | N4: ภาษี | O4: ปกส. | P4: สหกรณ์ | Q4: ฌกส. | R4: ออมสิน | S4: กยศ. | T4: ไฟฟ้า | U4: ประปา | V4: รับจริง
A8: 1 | B8: นางประเสริฐศรี | C8: พวงผกา | D8: พนักงานซักฟอก | V8: =E8+F8+G8+H8+I8+J8+K8+L8+M8-N8-O8-P8-Q8-R8-S8-T8-U8 -> 0
A9: 2 | B9: นายวัชรากร | C9: สถานพงษ์ | D9: พนักงานทั่วไป | V9: =E9+F9+G9+H9+I9+J9+K9+L9+M9-N9-O9-P9-Q9-R9-S9-T9-U9 -> 0
A10: 3 | B10: นางหวาน | C10: ตรีครุธพันธ์ | D10: แม่บ้าน | E10: 7 | V10: =E10+F10+G10+H10+I10+J10+K10+L10+M10-N10-O10-P10-Q10-R10-S10-T10-U10 -> 7
A11: 4 | B11: น.ส.บังอร | C11: ตรีครุธพันธ์ | D11: แม่บ้าน | V11: =E11+F11+G11+H11+I11+J11+K11+L11+M11-N11-O11-P11-Q11-R11-S11-T11-U11 -> 0
A12: 5 | B12: น.ส.วารุณี | C12: สอนมาลา | D12: แม่บ้าน | V12: =E12+F12+G12+H12+I12+J12+K12+L12+M12-N12-O12-P12-Q12-R12-S12-T12-U12 -> 0
A13: 6 | B13: นายศุภมิตร | C13: มีผล | D13: พนักงานการแพทย์และรังสีเทคนิค | V13: =E13+F13+G13+H13+I13+J13+K13+L13+M13-N13-O13-P13-Q13-R13-S13-T13-U13 -> 0
A14: 7 | B14: นายสุนันท์ | C14: เกษรสันติ์ | D14: พนักงานช่วยเหลือคนไข้ | V14: =E14+F14+G14+H14+I14+J14+K14+L14+M14-N14-O14-P14-Q14-R14-S14-T14-U14 -> 0
A15: 8 | B15: น.ส.นภา | C15: อนุเคราะห์ | D15: แม่บ้าน | V15: =E15+F15+G15+H15+I15+J15+K15+L15+M15-N15-O15-P15-Q15-R15-S15-T15-U15 -> 0
A16: 9 | B16: นายกิตติภพ | C16: แผ่พร | D16: พนักงานประจำห้องทดลอง | V16: =E16+F16+G16+H16+I16+J16+K16+L16+M16-N16-O16-P16-Q16-R16-S16-T16-U16 -> 0
A17: 10 | B17: น.ส.ชลนิชา | C17: นาคจันทร์ | D17: พนักงานช่วยเหลือคนไข้ | V17: =E17+F17+G17+H17+I17+J17+K17+L17+M17-N17-O17-P17-Q17-R17-S17-T17-U17 -> 0
A18: 11 | B18: นายอนุพงศ์ | C18: ยิ้มอ่อน | D18: พนักงานช่วยเหลือคนไข้ | V18: =E18+F18+G18+H18+I18+J18+K18+L18+M18-N18-O18-P18-Q18-R18-S18-T18-U18 -> 0
A19: 12 | B19: นายธนพงศ์ | C19: ทัพวิโรจน์ | D19: พนักงานขับรถยนต์ | V19: =E19+F19+G19+H19+I19+J19+K19+L19+M19-N19-O19-P19-Q19-R19-S19-T19-U19 -> 0
A20: 13 | B20: น.ส.สุนารี | C20: เกิดทวี | D20: เจ้าพนักงานการเงินและบัญชี | V20: =E20+F20+G20+H20+I20+J20+K20+L20+M20-N20-O20-P20-Q20-R20-S20-T20-U20 -> 0
A21: 14 | B21: นายประจิตร | C21: โสภา | D21: จพง.วิทยาศาสตร์การแพทย์ | V21: =E21+F21+G21+H21+I21+J21+K21+L21+M21-N21-O21-P21-Q21-R21-S21-T21-U21 -> 0
A22: 15 | B22: น.ส.อัญชลี | C22: แสงทอง | D22: แม่บ้าน | V22: =E22+F22+G22+H22+I22+J22+K22+L22+M22-N22-O22-P22-Q22-R22-S22-T22-U22 -> 0
... A25: 18 | B25: น.ส.ธันยา | C25: น้ำจันทร์เจริญ | D25: พนักงานช่วยเหลือคนไข้ | V25: =E25+F25+G25+H25+I25+J25+K25+L25+M25-N25-O25-P25-Q25-R25-S25-T25-U25 -> 0
A26: ยอดยกไป | E26: =SUM(E8:E25) -> 7 | F26: =SUM(F8:F25) -> 0 | G26: =SUM(G8:G25) -> 0 | H26: =SUM(H8:H25) -> 0 | I26: =SUM(I8:I25) -> 0 | J26: =SUM(J8:J25) -> 0 | K26: =SUM(K8:K25) -> 0 | L26: =SUM(L8:L25) -> 0 | ... V26: =SUM(V8:V25) -> 7
A27: ยอดยกมา | E27: =E26 -> 7 | F27: =F26 -> 0 | G27: =G26 -> 0 | H27: =H26 -> 0 | I27: =I26 -> 0 | J27: =J26 -> 0 | K27: =K26 -> 0 | L27: =L26 -> 0 | ... V27: =V26 -> 7
A28: 19 | B28: นายภูการ | C28: วงษ์เดือน | D28: พนักงานทั่วไป | V28: =E28+F28+G28+H28+I28+J28+K28+L28+M28-N28-O28-P28-Q28-R28-S28-T28-U28 -> 0
A29: 20 | B29: น.ส.เพ็ญพิสุทธิ์ | C29: โพธิจักร์ | D29: ผู้ช่วยนักกายภาพบำบัด | V29: =E29+F29+G29+H29+I29+J29+K29+L29+M29-N29-O29-P29-Q29-R29-S29-T29-U29 -> 0
A30: 21 | B30: น.ส.ณภัชภรน์ | C30: ทองสุข | D30: พนักงานช่วยเหลือคนไข้ | V30: =E30+F30+G30+H30+I30+J30+K30+L30+M30-N30-O30-P30-Q30-R30-S30-T30-U30 -> 0
A31: 22 | B31: น.ส.ณัฐลดา | C31: บัวจันทร์แดง | D31: พนักงานบริการ | V31: =E31+F31+G31+H31+I31+J31+K31+L31+M31-N31-O31-P31-Q31-R31-S31-T31-U31 -> 0
A32: 23 | B32: น.ส.ศศิธร | C32: เชื้ออ่อน | D32: พนักงานช่วยเหลือคนไข้ | V32: =E32+F32+G32+H32+I32+J32+K32+L32+M32-N32-O32-P32-Q32-R32-S32-T32-U32 -> 0
A33: 24 | B33: น.ส.อุบลฤดี | C33: บุตรชา | D33: พนักงานประจำห้องทดลอง | V33: =E33+F33+G33+H33+I33+J33+K33+L33+M33-N33-O33-P33-Q33-R33-S33-T33-U33 -> 0
A34: 26 | B34: นายอัครชัย | C34: อุบลพงษ์ | D34: พนักงานช่วยเหลือคนไข้ | V34: =E34+F34+G34+H34+I34+J34+K34+L34+M34-N34-O34-P34-Q34-R34-S34-T34-U34 -> 0
A35: 27 | B35: น.ส.ภัทรสุดา | C35: มงคลธง | D35: พนักงานช่วยเหลือคนไข้ | V35: =E35+F35+G35+H35+I35+J35+K35+L35+M35-N35-O35-P35-Q35-R35-S35-T35-U35 -> 0
A36: 28 | B36: น.ส.เปมิกา | C36: นนทอ | D36: พนักงานประจำห้องยา | V36: =E36+F36+G36+H36+I36+J36+K36+L36+M36-N36-O36-P36-Q36-R36-S36-T36-U36 -> 0
A37: 29 | B37: นางวิภาพร | C37: วังสันต์ | D37: แม่บ้าน | V37: =E37+F37+G37+H37+I37+J37+K37+L37+M37-N37-O37-P37-Q37-R37-S37-T37-U37 -> 0
A38: 30 | B38: นายวีระพงษ์ | C38: อ่างแก้ว | D38: พนักงานขับรถยนต์ | V38: =E38+F38+G38+H38+I38+J38+K38+L38+M38-N38-O38-P38-Q38-R38-S38-T38-U38 -> 0
A39: 31 | B39: น.ส.ปวริศา | C39: จันทา | D39: พนักงานช่วยเหลือคนไข้ | V39: =E39+F39+G39+H39+I39+J39+K39+L39+M39-N39-O39-P39-Q39-R39-S39-T39-U39 -> 0
... A44: 37 | B44: นายอนุกูล | C44: นาประดิษฐ | D44: พนักงานขับรถยนต์ | V44: =E44+F44+G44+H44+I44+J44+K44+L44+M44-N44-O44-P44-Q44-R44-S44-T44-U44 -> 0
A45: ยอดยกไป | E45: =SUM(E27:E44) -> 7 | F45: =SUM(F27:F44) -> 0 | G45: =SUM(G27:G44) -> 0 | H45: =SUM(H27:H44) -> 0 | I45: =SUM(I27:I44) -> 0 | J45: =SUM(J27:J44) -> 0 | K45: =SUM(K27:K44) -> 0 | L45: =SUM(L27:L44) -> 0 | ... V45: =SUM(V27:V44) -> 7
A46: ยอดยกมา | E46: =E45 -> 7 | F46: =F45 -> 0 | G46: =G45 -> 0 | H46: =H45 -> 0 | I46: =I45 -> 0 | J46: =J45 -> 0 | K46: =K45 -> 0 | L46: =L45 -> 0 | ... V46: =V45 -> 7
A47: 38 | B47: นายวิชัย | C47: วิดประโคน | D47: พนักงานบริการ(คนสวน) | V47: =E47+F47+G47+H47+I47+J47+K47+L47+M47-N47-O47-P47-Q47-R47-S47-T47-U47 -> 0
A48: 39 | B48: น.ส.สุนิสา | C48: ไทยรัตน์ | D48: นักวิชาการสาธารณสุข | V48: =E48+F48+G48+H48+I48+J48+K48+L48+M48-N48-O48-P48-Q48-R48-S48-T48-U48 -> 0
A49: 40 | B49: น.ส.สริมา | C49: งามไพบูลย์สมบัติ | D49: นายแพทย์ | V49: =E49+F49+G49+H49+I49+J49+K49+L49+M49-N49-O49-P49-Q49-R49-S49-T49-U49 -> 0
...

Sheet ช่วย
A1: รายละเอียดเงินเดือน โรงพยาบาลสามโคก
A2: =[1]ข้าราชการ!A2 -> ประจำเดือนพฤศจิกายน 2568
A3: ที่ | B3: ชื่อ - นามสกุล | D3: รายรับ | N3: รายจ่าย
D4: ตำแหน่ง | E4: เงินเดือน | F4: เงินตำแหน่ง | G4: เงินเพิ่มพิเศษไม่ทำเวชปฏิบัติ | H4: ค่าตอบแทนพตส. | I4: ค่าตอบแทน ฉ.11 ตค.68 | J4: ค่าตอบแทนนอกเวลา ราชการ ตค.68 | K4: ค่าตอบแทนจิตแพทย์ พย.68 | L4: ค่าการศึกษาบุตร | M4: ค่ารักษาพยาบาล | N4: อื่นๆ | O4: ปกส. | P4: สหกรณ์ | Q4: ฌกส. | R4: ออมสิน | S4: กรุงไทย | T4: ไฟฟ้า | U4: ประปา | V4: รับจริง
A8: 1 | B8: นายประกาศ | C8: เปล่งพานิชย์ | J8: 2 | V8: =E8+F8+G8+H8+I8+J8+K8+L8+M8-N8-O8-P8-Q8-R8-S8-T8-U8 -> 2
A9: 2 | B9: น.ส.น้ำฝน | C9: วงษ์เพ็ง | V9: =E9+F9+G9+H9+I9+J9+K9+L9+M9-N9-O9-P9-Q9-R9-S9-T9-U9 -> 0
A10: 3 | B10: น.ส.ณัฐนรี | C10: รัตนวงศ์ | V10: =E10+F10+G10+H10+I10+J10+K10+L10+M10-N10-O10-P10-Q10-R10-S10-T10-U10 -> 0
A11: 4 | B11: น.ส.ฟารีดา | C11: อาดำ | V11: =E11+F11+G11+H11+I11+J11+K11+L11+M11-N11-O11-P11-Q11-R11-S11-T11-U11 -> 0
A12: 5 | B12: น.ส.ฟารีดา | C12: คชฤทธิ์ | V12: =E12+F12+G12+H12+I12+J12+K12+L12+M12-N12-O12-P12-Q12-R12-S12-T12-U12 -> 0
A13: 6 | B13: น.ส.ปรียาภรณ์ | C13: ขันทอง | V13: =E13+F13+G13+H13+I13+J13+K13+L13+M13-N13-O13-P13-Q13-R13-S13-T13-U13 -> 0
A14: 7 | B14: นายดนัย | C14: บางชวด | V14: =E14+F14+G14+H14+I14+J14+K14+L14+M14-N14-O14-P14-Q14-R14-S14-T14-U14 -> 0
A15: 8 | B15: นางรักษ์สินี | C15: ชอบดี | V15: =E15+F15+G15+H15+I15+J15+K15+L15+M15-N15-O15-P15-Q15-R15-S15-T15-U15 -> 0
A16: 9 | B16: นายประยุกต์ | C16: เสรีเสถียร | V16: =E16+F16+G16+H16+I16+J16+K16+L16+M16-N16-O16-P16-Q16-R16-S16-T16-U16 -> 0
A17: 10 | B17: น.ส.รัชนี | C17: ฉลองเกื้อกูล | K17: 40 | V17: =E17+F17+G17+H17+I17+J17+K17+L17+M17-N17-O17-P17-Q17-R17-S17-T17-U17 -> 40
A18: 11 | B18: นางวนิดา | C18: ศรีศัมภุวงศ์ | V18: =E18+F18+G18+H18+I18+J18+K18+L18+M18-N18-O18-P18-Q18-R18-S18-T18-U18 -> 0
A19: 12 | B19: น.ส.สุภาภรณ์ | C19: มานสพานสูง | V19: =E19+F19+G19+H19+I19+J19+K19+L19+M19-N19-O19-P19-Q19-R19-S19-T19-U19 -> 0
A20: 13 | B20: นายคิวณัฐ | C20: สาราเอก | V20: =E20+F20+G20+H20+I20+J20+K20+L20+M20-N20-O20-P20-Q20-R20-S20-T20-U20 -> 0
A21: 14 | B21: น.ส.กัญญารัตน์ | C21: คำรักษ์ | V21: =E21+F21+G21+H21+I21+J21+K21+L21+M21-N21-O21-P21-Q21-R21-S21-T21-U21 -> 0
A22: 15 | B22: น.ส.อ้อมขวัญ | C22: ศิริจร | V22: =E22+F22+G22+H22+I22+J22+K22+L22+M22-N22-O22-P22-Q22-R22-S22-T22-U22 -> 0
A23: 16 | B23: น.ส.สุภาวดี | C23: จริยาธนประภา | V23: =E23+F23+G23+H23+I23+J23+K23+L23+M23-N23-O23-P23-Q23-R23-S23-T23-U23 -> 0
A24: 17 | B24: นางปัทมาพร | C24: อ่านเปรื่อง | V24: =E24+F24+G24+H24+I24+J24+K24+L24+M24-N24-O24-P24-Q24-R24-S24-T24-U24 -> 0
A25: 18 | B25: น.ส.ปัทมาภร | C25: ชื่นยินดี | V25: =E25+F25+G25+H25+I25+J25+K25+L25+M25-N25-O25-P25-Q25-R25-S25-T25-U25 -> 0
A26: 19 | B26: น.ส.ณภวรรณ | C26: นันเพ็ญ | V26: =E26+F26+G26+H26+I26+J26+K26+L26+M26-N26-O26-P26-Q26-R26-S26-T26-U26 -> 0
A27: รวมทั้งสิ้น | E27: =SUM(E8:E26) -> 0 | F27: =SUM(F8:F26) -> 0 | G27: =SUM(G8:G26) -> 0 | H27: =SUM(H8:H26) -> 0 | I27: =SUM(I8:I26) -> 0 | J27: =SUM(J8:J26) -> 2 | K27: =SUM(K8:K26) -> 40 | L27: =SUM(L8:L26) -> 0 | ... V27: =SUM(V8:V26) -> 42

Sheet สรุป
A1: สรุปการรับ - จ่ายเงินเข้าบัญชี | C1: ประจำเดือน | D1: พฤศจิกายน | F1: 2568
A2: ฎีกาที่ | B2: รายการ | C2: เบิก | D2: หัก | E2: จำนวน | F2: รับจริง | G2: สสจ.โอนเงิน
A3: รายรับ
B4: เงินบำรุงกรุงไทย
A5: - | B5: เงินเพิ่มพิเศษแพทย์,ทันต,เภสัช ไม่ทำเวช พ.ย.68 | C5: 200 | F5: =C5-E5 -> 200
A6: - | B6: ค่าจ้างพนักงานกระทรวงสาธารณสุข พ.ย.68 | C6: 30 | F6: =C6-E6 -> 30
A7: - | B7: ค่าจ้างลูกจ้างชั่วคราวรายเดือน พ.ย.68 | C7: 4 | F7: =C7-E7 -> 4
A8: - | B8: ค่าจ้างลูกจ้างชั่วคราวรายวัน พ.ย.68 | C8: 7 | F8: =C8-E8 -> 7
A9: - | B9: ค่าตอบแทน พตส. พฤศจิกายน 2568 | C9: 50 | F9: =C9-E9 -> 50
A10: - | B10: ค่าตอบแทนปฏิบัติงานนอกเวลา OT ต.ค.68 | C10: 5 | F10: =C10-E10 -> 5
A11: - | B11: ค่าตอบแทนปฏิบัติงานนอกเวลา OT ต.ค.68 (การคลัง) | C11: 3 | F11: =C11-E11 -> 3
A12: - | B12: ค่าตอบแทน ฉ.11 ต.ค.68 (สนับสนุน) | C12: 12 | F12: =C12-E12 -> 12
A13: - | B13: กองทุนสำรองเลี้ยงชีพ พนักงานกระทรวงสาธารณสุข | C13: 1 | F13: =C13-E13 -> 1
A14: - | B14: ค่าตอบแทนจิตแพทย์ พ.ย.68 | C14: 40 | F14: =C14-E14 -> 40
A15: - | B15: ค่าตอบแทนแพทย์สาขาส่งเสริมพิเศษ พ.ย.68 | C15: 20 | F15: =C15-E15 -> 20
A16: - | B16: ค่าตอบแทนพิเศษ น.ส.เบญจวรรณ สุขชูศรี ต.ค. - พ.ย.68 | C16: 500 | F16: =C16-E16 -> 500
A17: - | B17: ตกเบิกเงินเดือนพนักงานกระทรวง ตุลาคม 2568 | C17: 3 | F17: =C17-E17 -> 3
B28: รวมรับ | C28: =SUM(C3:C26) -> 875 | E28: =SUM(E3:E14) -> 0 | F28: =SUM(F4:F26) -> 875
A29: รายจ่าย | B29: สหกรณ์ออมทรัพย์สาธารณสุขปทุมธานี | F29: 1 | G29: kl
B30: ฌกส. (ฌาปนกิจสงเคราะห์ของกระทรวงสาธารณสุข) | F30: 1 | G30: kl
B31: เข้าบัญชีเจ้าหน้าที่ (บัญชีข้าราชการ/ลูกจ้าง) | F31: 857 | G31: kl
B32: สินเชื่อสวัสดิการธนาคารออมสิน สาขาปทุมธานี | F32: 0 | G32: kl
B33: สินเชื่อสวัสดิการธนาคารออมสิน สาขาทียูโดม รังสิต | F33: 2 | G33: kl
B34: สินเชื่อสวัสดิการธนาคารกรุงไทย สาขาอำเภอสามโคก | F34: 10 | G34: kl
B35: กองทุนสำรองเลี้ยงชีพ พนักงานกระทรวงสาธารณสุข ซึ่งจดทะเบียนแล้ว | F35: 2 | G35: kl
B36: กรมสรรพากร 2 เพื่อรับชำระเงินคืนกองทุนเงินให้กู้ยืมเพื่อการศึกษา | F36: 2 | G36: kl
E37: รวมจ่าย | F37: =SUM(F29:F36) -> 875 | I37: =F28+E28-F37 -> 0 | J37: เท่ากับ 0 แปลว่าตรง
B39: หมายเหตุ | C39: กลุ่ม 000001 (เงินเดือน+ค่าจ้างลูกจ้าง) | G39: =K46 -> 853 | H39: รวมใบขวาง | I39: รวมน้ำไฟ+ปกส. | K39: =ข้าราชการ!V75 -> 210
B40: ค่าไฟฟ้า-น้ำประปา | D40: เข้าบัญชี รพ.สามโคก | G40: 2 | I40: =G40+G41+G42 -> 4 | K40: =ลจ.ประจำ!V23 -> 10
B41: ประกันสังคม | D41: เข้าบัญชี รพ.สามโคก | G41: 2 | K41: =พนักงาน!V24 -> 5
K42: =พกส.!W43 -> 576
C43: ยอดที่นำเข้าบัญชีทั้งหมด คือ | G43: =SUM(G39:G42) -> 857 | K43: =รายเดือน!V26 -> 3
K44: =รายวัน!V55 -> 7
K45: =ช่วย!V27 -> 42
K46: =SUM(K39:K45) -> 853

Sheet ขร1
A1: โรงพยาบาลสามโคก ประจำเดือน พฤศจิกายน 2568 | J1: =A1 -> โรงพยาบาลสามโคก ประจำเดือน พฤศจิกายน 2568
A2: ชื่อ นายจตุพงษ์ จันทร์ทอง ตำแหน่ง นายแพทย์ชำนาญการพิเศษ | J2: ชื่อ นางวิริยา มาตรา ตำแหน่ง เภสัชกรชำนาญการ
B4: รายรับ | G4: รายจ่าย | K4: รายรับ | P4: รายจ่าย
B5: เงินเดือน | D5: =ข้าราชการ!E8 -> 0 | G5: ภาษี | H5: =ข้าราชการ!N8 -> 0 | K5: เงินเดือน | M5: =ข้าราชการ!E20 -> 0 | P5: ภาษี | Q5: =ข้าราชการ!N20 -> 0
B6: เงินประจำตำแหน่ง/เท่าตำแหน่ง | D6: =ข้าราชการ!F8 -> 0 | G6: กบข. | H6: =ข้าราชการ!O8 -> 0 | K6: เงินประจำตำแหน่ง/เท่าตำแหน่ง | M6: =ข้าราชการ!F20 -> 0 | P6: กบข. | Q6: =ข้าราชการ!O20 -> 0
B7: เงินเพิ่มพิเศษไม่ทำเวชปฏิบัติ | D7: =ข้าราชการ!G8 -> 200 | G7: สหกรณ์ | H7: =ข้าราชการ!P8 -> 0 | K7: เงินเพิ่มพิเศษไม่ทำเวชปฏิบัติ พ.ย.68 | M7: =ข้าราชการ!G20 -> 0 | P7: สหกรณ์ | Q7: =ข้าราชการ!P20 -> 0
B8: ค่าตอบแทน พตส. | D8: =ข้าราชการ!H8 -> 0 | G8: ฌาปณกิจสงเคราะห์ | H8: =ข้าราชการ!Q8 -> 0 | K8: ค่าตอบแทน พตส. | M8: =ข้าราชการ!H20 -> 0 | P8: ฌาปณกิจสงเคราะห์ | Q8: =ข้าราชการ!Q20 -> 0
B9: ค่าตอบแทน ฉ.11 | D9: =ข้าราชการ!I8 -> 0 | G9: ออมสิน | H9: =ข้าราชการ!R8 -> 0 | K9: ค่าตอบแทน ฉ.11 | M9: =ข้าราชการ!I20 -> 0 | P9: ออมสิน | Q9: =ข้าราชการ!R20 -> 0
B10: ค่าตอบแทนนอกเวลาราชการ | D10: =ข้าราชการ!J8 -> 0 | G10: กรุงไทย | H10: =ข้าราชการ!S8 -> 10 | K10: ค่าตอบแทนนอกเวลาราชการ | M10: =ข้าราชการ!J20 -> 0 | P10: กรุงไทย | Q10: =ข้าราชการ!S20 -> 0
B11: ค่าตอบแทนพิเศษแพทย์ พ.ย.68 | D11: =ข้าราชการ!K8 -> 20 | G11: ไฟฟ้า | H11: =ข้าราชการ!T8 -> 0 | K11: ตกเบิกเงินเดือน | M11: =ข้าราชการ!K20 -> 0 | P11: ไฟฟ้า | Q11: =ข้าราชการ!T20 -> 0
B12: ค่าการศึกษาบุตร | D12: =ข้าราชการ!L8 -> 0 | G12: ประปา | H12: =ข้าราชการ!U8 -> 0 | K12: ค่าการศึกษาบุตร | M12: =ข้าราชการ!L20 -> 0 | P12: ประปา | Q12: =ข้าราชการ!U20 -> 0
B13: ค่ารักษาพยาบาล | D13: =ข้าราชการ!M8 -> 0 | K13: ค่ารักษาพยาบาล | M13: =ข้าราชการ!M20 -> 0
B14: รวมรับ | D14: =SUM(D5:D13) -> 220 | G14: รวมจ่าย | H14: =SUM(H5:H13) -> 10 | K14: รวมรับ | M14: =SUM(M5:M13) -> 0 | P14: รวมจ่าย | Q14: =SUM(Q5:Q13) -> 0
C15: คงเหลือสุทธิ | D15: =D14-H14 -> 210 | F15: บาท | L15: คงเหลือสุทธิ | M15: =M14-Q14 -> 0 | O15: บาท
C16: ="("&BAHTTEXT(D15)&")" -> (สองร้อยสิบบาทถ้วน) | L16: ="("&BAHTTEXT(M15)&")" -> (ศูนย์บาทถ้วน)
A21: (นางสาวพนิดา พลนงค์) | J21: (นางสาวพนิดา พลนงค์)
A22: นักจัดการงานทั่วไปปฏิบัติการ | K22: นักจัดการงานทั่วไปปฏิบัติการ
A23: =A1 -> โรงพยาบาลสามโคก ประจำเดือน พฤศจิกายน 2568 | J23: =A1 -> โรงพยาบาลสามโคก ประจำเดือน พฤศจิกายน 2568
A24: ชื่อ นางสาวนิตยา สารีกิจ ตำแหน่ง พยาบาลวิชาชีพปฏิบัติการ | J24: ชื่อ นางสาวสำรวย ทั่งรื่น ตำแหน่ง เจ้าพนักงานเภสัชกรรมชำนาญงาน
B26: รายรับ | G26: รายจ่าย | K26: รายรับ | P26: รายจ่าย
B27: เงินเดือน | D27: 0 | G27: ภาษี | H27: =ข้าราชการ!E43 -> 0 | K27: เงินเดือน | M27: =ข้าราชการ!E21 -> 0 | P27: ภาษี | Q27: =ข้าราชการ!N21 -> 0
B28: เงินประจำตำแหน่ง/เท่าตำแหน่ง | D28: 0 | G28: กบข. | H28: =ข้าราชการ!F43 -> 0 | K28: เงินประจำตำแหน่ง/เท่าตำแหน่ง | M28: =ข้าราชการ!F21 -> 0 | P28: กบข. | Q28: =ข้าราชการ!O21 -> 0
B29: เงินเพิ่มพิเศษไม่ทำเวชปฏิบัติ | D29: 0 | G29: สหกรณ์ | H29: 0 | K29: เงินเพิ่มพิเศษไม่ทำเวชปฏิบัติ | M29: =ข้าราชการ!G21 -> 0 | P29: สหกรณ์ | Q29: =ข้าราชการ!P21 -> 0
B30: ค่าตอบแทน พตส. | D30: =ข้าราชการ!H9 -> 0 | G30: ฌาปณกิจสงเคราะห์ | H30: =ข้าราชการ!Q9 -> 0 | K30: ค่าตอบแทน พตส. | M30: =ข้าราชการ!H21 -> 0 | P30: ฌาปณกิจสงเคราะห์ | Q30: =ข้าราชการ!Q21 -> 0
B31: ค่าตอบแทน ฉ.11 | D31: =ข้าราชการ!I9 -> 0 | G31: ออมสิน | H31: 0 | K31: ค่าตอบแทน ฉ.11 | M31: =ข้าราชการ!I21 -> 0 | P31: ออมสิน | Q31: =ข้าราชการ!R21 -> 0
B32: ค่าตอบแทนนอกเวลาราชการ ต.ค.68 | D32: =ข้าราชการ!J9 -> 0 | G32: กรุงไทย | H32: 0 | K32: ค่าตอบแทนนอกเวลาราชการ ต.ค.68 | M32: =ข้าราชการ!J21 -> 0 | P32: กรุงไทย | Q32: =ข้าราชการ!S21 -> 0
B33: ตกเบิกเงินเดือน | D33: =ข้าราชการ!K9 -> 0 | G33: ไฟฟ้า | H33: =ข้าราชการ!T9 -> 0 | K33: ตกเบิกเงินเดือน | M33: =ข้าราชการ!K21 -> 0 | P33: ไฟฟ้า | Q33: =ข้าราชการ!T21 -> 0
B34: ค่าการศึกษาบุตร | D34: =ข้าราชการ!L9 -> 0 | G34: ประปา | H34: =ข้าราชการ!U9 -> 0 | K34: ค่าการศึกษาบุตร | M34: =ข้าราชการ!L21 -> 0 | P34: ประปา | Q34: =ข้าราชการ!U21 -> 0
B35: ค่ารักษาพยาบาล | D35: =ข้าราชการ!D43 -> 0 | K35: ค่ารักษาพยาบาล | M35: =ข้าราชการ!M21 -> 0
B36: รวมรับ | D36: =SUM(D27:D35) -> 0 | G36: รวมจ่าย | H36: =SUM(H27:H35) -> 0 | K36: รวมรับ | M36: =SUM(M27:M35) -> 0 | P36: รวมจ่าย | Q36: =SUM(Q27:Q35) -> 0
C37: คงเหลือสุทธิ | D37: =D36-H36 -> 0 | F37: บาท | L37: คงเหลือสุทธิ | M37: =M36-Q36 -> 0 | O37: บาท
C38: ="("&BAHTTEXT(D37)&")" -> (ศูนย์บาทถ้วน) | L38: ="("&BAHTTEXT(M37)&")" -> (ศูนย์บาทถ้วน)
A43: (นางสาวพนิดา พลนงค์) | K43: (นางสาวพนิดา พลนงค์)
A44: นักจัดการงานทั่วไปปฏิบัติการ | K44: นักจัดการงานทั่วไปปฏิบัติการ
A45: =A1 -> โรงพยาบาลสามโคก ประจำเดือน พฤศจิกายน 2568 | J45: =A1 -> โรงพยาบาลสามโคก ประจำเดือน พฤศจิกายน 2568
A46: ชื่อ นางสาวพนิดา พลนงค์ ตำแหน่ง นักจัดการงานทั่วไปปฏิบัติการ | J46: ชื่อ นางสาวสนธยา เชี่ยวชายชำนาญกิจ ตำแหน่ง เภสัชกรชำนาญการ
B48: รายรับ | G48: รายจ่าย | K48: รายรับ | P48: รายจ่าย
B49: เงินเดือน | D49: 0 | G49: ภาษี | H49: 0 | K49: เงินเดือน | M49: =ข้าราชการ!E22 -> 0 | P49: ภาษี | Q49: =ข้าราชการ!N22 -> 0
B50: เงินประจำตำแหน่ง/เท่าตำแหน่ง | D50: =ข้าราชการ!F10 -> 0 | G50: กบข. | H50: 0 | K50: เงินประจำตำแหน่ง/เท่าตำแหน่ง | M50: =ข้าราชการ!F22 -> 0 | P50: กบข. | Q50: =ข้าราชการ!O22 -> 0
B51: เงินเพิ่มพิเศษไม่ทำเวชปฏิบัติ | D51: =ข้าราชการ!G10 -> 0 | G51: สหกรณ์ | H51: 0 | K51: เงินเพิ่มพิเศษไม่ทำเวชปฏิบัติ | M51: =ข้าราชการ!G22 -> 0 | P51: สหกรณ์ | Q51: =ข้าราชการ!P22 -> 0
...

Sheet ขร2
A1: =ขร1!A1 -> โรงพยาบาลสามโคก ประจำเดือน พฤศจิกายน 2568 | J1: =ขร1!J243 -> โรงพยาบาลสามโคก ประจำเดือน พฤศจิกายน 2568
A2: ชื่อ นางสาวจีรวัจน์ ฤทธิรณ ตำแหน่ง พยาบาลวิชาชีพชำนาญการ | J2: ชื่อ นางสาวรจนา สาสาร ตำแหน่ง พยาบาลวิชาชีพปฏิบัติการ
B4: รายรับ | G4: รายจ่าย | K4: รายรับ | P4: รายจ่าย
B5: เงินเดือน | D5: =ข้าราชการ!E32 -> 0 | G5: ภาษี | H5: =ข้าราชการ!N32 -> 0 | K5: เงินเดือน | M5: =ข้าราชการ!E45 -> 0 | P5: ภาษี | Q5: =ข้าราชการ!N45 -> 0
B6: เงินประจำตำแหน่ง/เท่าตำแหน่ง | D6: =ข้าราชการ!F32 -> 0 | G6: กบข. | H6: =ข้าราชการ!O32 -> 0 | K6: เงินประจำตำแหน่ง/เท่าตำแหน่ง | M6: =ข้าราชการ!F45 -> 0 | P6: กบข. | Q6: =ข้าราชการ!O45 -> 0
B7: เงินเพิ่มพิเศษไม่ทำเวชปฏิบัติ | D7: =ข้าราชการ!G32 -> 0 | G7: สหกรณ์ | H7: =ข้าราชการ!P32 -> 0 | K7: เงินเพิ่มพิเศษไม่ทำเวชปฏิบัติ | M7: =ข้าราชการ!G45 -> 0 | P7: สหกรณ์ | Q7: =ข้าราชการ!P45 -> 0
B8: ค่าตอบแทน พตส. | D8: =ข้าราชการ!H34 -> 0 | G8: ฌาปณกิจสงเคราะห์ | H8: =ข้าราชการ!Q32 -> 0 | K8: ค่าตอบแทน พตส. | M8: =ข้าราชการ!H47 -> 0 | P8: ฌาปณกิจสงเคราะห์ | Q8: =ข้าราชการ!Q45 -> 0
B9: ค่าตอบแทน ฉ.11 | D9: =ข้าราชการ!I34 -> 0 | G9: ออมสิน | H9: =ข้าราชการ!R32 -> 0 | K9: ค่าตอบแทน ฉ.11 | M9: =ข้าราชการ!I47 -> 0 | P9: ออมสิน | Q9: =ข้าราชการ!R47 -> 0
B10: ค่าตอบแทนนอกเวลาราชการ ต.ค.68 | D10: =ข้าราชการ!J34 -> 0 | G10: กรุงไทย | H10: 0 | K10: ค่าตอบแทนนอกเวลาราชการ ต.ค.68 | M10: =ข้าราชการ!J47 -> 0 | P10: กรุงไทย | Q10: =ข้าราชการ!S47 -> 0
B11: ตกเบิกเงินเดือน | D11: 0 | G11: ไฟฟ้า | H11: 0 | K11: ตกเบิกเงินเดือน | M11: =ข้าราชการ!K45 -> 0 | P11: ไฟฟ้า | Q11: =ข้าราชการ!T47 -> 0
B12: ค่าการศึกษาบุตร | D12: =ข้าราชการ!L32 -> 0 | G12: ประปา | H12: 0 | K12: ค่าการศึกษาบุตร | M12: =ข้าราชการ!L45 -> 0 | P12: ประปา | Q12: =ข้าราชการ!U47 -> 0
B13: ค่ารักษาพยาบาล | D13: =ข้าราชการ!M32 -> 0 | K13: ค่ารักษาพยาบาล | M13: =ข้าราชการ!M45 -> 0
B14: รวมรับ | D14: =SUM(D5:D13) -> 0 | G14: รวมจ่าย | H14: =SUM(H5:H13) -> 0 | K14: รวมรับ | M14: =SUM(M5:M13) -> 0 | P14: รวมจ่าย | Q14: =SUM(Q5:Q13) -> 0
C15: คงเหลือสุทธิ | D15: =D14-H14 -> 0 | F15: บาท | L15: คงเหลือสุทธิ | M15: =M14-Q14 -> 0 | O15: บาท
C16: ="("&BAHTTEXT(D15)&")" -> (ศูนย์บาทถ้วน) | L16: ="("&BAHTTEXT(M15)&")" -> (ศูนย์บาทถ้วน)
A21: (นางสาวพนิดา พลนงค์) | J21: (นางสาวพนิดา พลนงค์)
A22: นักจัดการงานทั่วไปปฏิบัติการ | J22: นักจัดการงานทั่วไปปฏิบัติการ
A23: =ขร1!J243 -> โรงพยาบาลสามโคก ประจำเดือน พฤศจิกายน 2568 | J23: =ขร2!A155 -> โรงพยาบาลสามโคก ประจำเดือน พฤศจิกายน 2568
A24: ชื่อ นางสาวพจนา พวงธรรม ตำแหน่ง พยาบาลวิชาชีพชำนาญการพิเศษ | J24: ชื่อ นางสาวจิตรวดี วิโรจน์ ตำแหน่ง พยาบาลวิชาชีพชำนาญการ
B26: รายรับ | G26: รายจ่าย | K26: รายรับ | P26: รายจ่าย
B27: เงินเดือน | D27: =ข้าราชการ!E33 -> 0 | G27: ภาษี | H27: =ข้าราชการ!N33 -> 0 | K27: เงินเดือน | M27: =ข้าราชการ!E46 -> 0 | P27: ภาษี | Q27: =ข้าราชการ!N46 -> 0
B28: เงินประจำตำแหน่ง/เท่าตำแหน่ง | D28: =ข้าราชการ!F33 -> 0 | G28: กบข. | H28: =ข้าราชการ!O33 -> 0 | K28: เงินประจำตำแหน่ง/เท่าตำแหน่ง | M28: =ข้าราชการ!F46 -> 0 | P28: กบข. | Q28: =ข้าราชการ!O46 -> 0
B29: เงินเพิ่มพิเศษไม่ทำเวชปฏิบัติ | D29: =ข้าราชการ!G33 -> 0 | G29: สหกรณ์ | H29: =ข้าราชการ!P33 -> 0 | K29: เงินเพิ่มพิเศษไม่ทำเวชปฏิบัติ | M29: =ข้าราชการ!G46 -> 0 | P29: สหกรณ์ | Q29: =ข้าราชการ!P46 -> 0
B30: ค่าตอบแทน พตส. | D30: =ข้าราชการ!H35 -> 0 | G30: ฌาปณกิจสงเคราะห์ | H30: =ข้าราชการ!Q33 -> 0 | K30: ค่าตอบแทน พตส. | M30: =ข้าราชการ!H48 -> 0 | P30: ฌาปณกิจสงเคราะห์ | Q30: =ข้าราชการ!Q48 -> 0
B31: ค่าตอบแทน ฉ.11 | D31: =ข้าราชการ!I35 -> 0 | G31: ออมสิน | H31: 0 | K31: ค่าตอบแทน ฉ.11 | M31: =ข้าราชการ!I48 -> 0 | P31: ออมสิน | Q31: =ข้าราชการ!R46 -> 0
B32: ค่าตอบแทนนอกเวลาราชการ ต.ค.68 | D32: =ข้าราชการ!J35 -> 0 | G32: กรุงไทย | H32: =ข้าราชการ!S35 -> 0 | K32: ค่าตอบแทนนอกเวลาราชการ ต.ค.68 | M32: =ข้าราชการ!J48 -> 0 | P32: กรุงไทย | Q32: =ข้าราชการ!S48 -> 0
B33: ตกเบิกเงินเดือน | D33: =ข้าราชการ!K33 -> 0 | G33: ไฟฟ้า | H33: =ข้าราชการ!T35 -> 0 | K33: ตกเบิกเงินเดือน | M33: =ข้าราชการ!K46 -> 0 | P33: ไฟฟ้า | Q33: =ข้าราชการ!T48 -> 0
B34: ค่าการศึกษาบุตร | D34: =ข้าราชการ!L33 -> 0 | G34: ประปา | H34: =ข้าราชการ!U35 -> 0 | K34: ค่าการศึกษาบุตร | M34: 0 | P34: ประปา | Q34: =ข้าราชการ!U48 -> 0
B35: ค่ารักษาพยาบาล | D35: =ข้าราชการ!M33 -> 0 | K35: ค่ารักษาพยาบาล | M35: =ข้าราชการ!M46 -> 0
B36: รวมรับ | D36: =SUM(D27:D35) -> 0 | G36: รวมจ่าย | H36: =SUM(H27:H35) -> 0 | K36: รวมรับ | M36: =SUM(M27:M35) -> 0 | P36: รวมจ่าย | Q36: =SUM(Q27:Q35) -> 0
C37: คงเหลือสุทธิ | D37: =D36-H36 -> 0 | F37: บาท | L37: คงเหลือสุทธิ | M37: =M36-Q36 -> 0 | O37: บาท
C38: ="("&BAHTTEXT(D37)&")" -> (ศูนย์บาทถ้วน) | L38: ="("&BAHTTEXT(M37)&")" -> (ศูนย์บาทถ้วน)
B43: (นางสาวพนิดา พลนงค์) | J43: (นางสาวพนิดา พลนงค์)
B44: นักจัดการงานทั่วไปปฏิบัติการ | J44: นักจัดการงานทั่วไปปฏิบัติการ
A45: =ขร1!J243 -> โรงพยาบาลสามโคก ประจำเดือน พฤศจิกายน 2568 | J45: =ขร1!J243 -> โรงพยาบาลสามโคก ประจำเดือน พฤศจิกายน 2568
A46: ชื่อ นางพรทิพย์ ธนเตชะสิน ตำแหน่ง พยาบาลวิชาชีพชำนาญการ | J46: ชื่อ นางสาวทิพาพร ดนตรีเสนาะ ตำแหน่ง พยาบาลวิชาชีพปฏิบัติการ
B48: รายรับ | G48: รายจ่าย | K48: รายรับ | P48: รายจ่าย
B49: เงินเดือน | D49: =ข้าราชการ!E34 -> 0 | G49: ภาษี | H49: =ข้าราชการ!N34 -> 0 | K49: เงินเดือน | M49: =ข้าราชการ!E47 -> 0 | P49: ภาษี | Q49: =ข้าราชการ!N47 -> 0
B50: เงินประจำตำแหน่ง/เท่าตำแหน่ง | D50: =ข้าราชการ!F34 -> 0 | G50: กบข. | H50: =ข้าราชการ!O34 -> 0 | K50: เงินประจำตำแหน่ง/เท่าตำแหน่ง | M50: =ข้าราชการ!F47 -> 0 | P50: กบข. | Q50: =ข้าราชการ!O47 -> 0
B51: เงินเพิ่มพิเศษไม่ทำเวชปฏิบัติ | D51: =ข้าราชการ!G34 -> 0 | G51: สหกรณ์ | H51: =ข้าราชการ!P34 -> 0 | K51: เงินเพิ่มพิเศษไม่ทำเวชปฏิบัติ | M51: =ข้าราชการ!G47 -> 0 | P51: สหกรณ์ | Q51: =ข้าราชการ!P47 -> 0
...

Sheet ขร3
A1: =ขร2!J111 -> โรงพยาบาลสามโคก ประจำเดือน พฤศจิกายน 2568 | J1: =A23 -> โรงพยาบาลสามโคก ประจำเดือน พฤศจิกายน 2568
A2: ชื่อ นายนรุตน์ ช่วยกลาง ตำแหน่ง ทันตแพทย์ปฏิบัติการ | J2: ชื่อ นางสาวจิระวดี กันทะมัง ตำแหน่ง นักวิชาการสาธารณสุขปฏิบัติการ
B4: รายรับ | G4: รายจ่าย | K4: รายรับ | P4: รายจ่าย
B5: เงินเดือน | D5: =ข้าราชการ!E55 -> 0 | G5: ภาษี | H5: 0 | K5: เงินเดือน | M5: 0 | P5: ภาษี | Q5: 0
B6: เงินประจำตำแหน่ง/เท่าตำแหน่ง | D6: 0 | G6: กบข. | H6: 0 | K6: เงินประจำตำแหน่ง/เท่าตำแหน่ง | M6: 0 | P6: กบข. | Q6: 0
B7: เงินเพิ่มพิเศษไม่ทำเวชปฏิบัติ | D7: 0 | G7: สหกรณ์ | H7: 0 | K7: เงินเพิ่มพิเศษไม่ทำเวชปฏิบัติ | M7: 0 | P7: สหกรณ์ | Q7: 0
B8: ค่าตอบแทน พตส. | D8: =ข้าราชการ!H57 -> 0 | G8: ฌาปณกิจสงเคราะห์ | H8: 0 | K8: ค่าตอบแทน พตส. | M8: 0 | P8: ฌาปณกิจสงเคราะห์ | Q8: 0
B9: ค่าตอบแทน ฉ.11 | D9: =ข้าราชการ!I57 -> 0 | G9: ออมสิน | H9: 0 | K9: ค่าตอบแทน ฉ.11 | M9: =ข้าราชการ!I70 -> 0 | P9: ออมสิน | Q9: 0
B10: ค่าตอบแทนนอกเวลาราชการ | D10: =ข้าราชการ!J57 -> 0 | G10: กรุงไทย | H10: =ข้าราชการ!S55 -> 0 | K10: ค่าตอบแทนนอกเวลาราชการ ต.ค.68 | M10: =ข้าราชการ!J69 -> 0 | P10: กรุงไทย | Q10: 0
B11: ตกเบิกเงินเดือน | D11: =ข้าราชการ!K55 -> 0 | G11: ไฟฟ้า | H11: =ข้าราชการ!T55 -> 0 | K11: ตกเบิกเงินเดือน | M11: =ข้าราชการ!K69 -> 0 | P11: ไฟฟ้า | Q11: =ข้าราชการ!T69 -> 0
B12: ค่าการศึกษาบุตร | D12: 0 | G12: ประปา | H12: =ข้าราชการ!U55 -> 0 | K12: ค่าการศึกษาบุตร | M12: 0 | P12: ประปา | Q12: =ข้าราชการ!U69 -> 0
B13: ค่ารักษาพยาบาล | D13: =ข้าราชการ!M55 -> 0 | K13: ค่ารักษาพยาบาล | M13: 0
B14: รวมรับ | D14: =SUM(D5:D13) -> 0 | G14: รวมจ่าย | H14: =SUM(H5:H13) -> 0 | K14: รวมรับ | M14: =SUM(M5:M13) -> 0 | P14: รวมจ่าย | Q14: =SUM(Q5:Q13) -> 0
C15: คงเหลือสุทธิ | D15: =D14-H14 -> 0 | F15: บาท | L15: คงเหลือสุทธิ | M15: =M14-Q14 -> 0 | O15: บาท
C16: ="("&BAHTTEXT(D15)&")" -> (ศูนย์บาทถ้วน) | L16: ="("&BAHTTEXT(M15)&")" -> (ศูนย์บาทถ้วน)
A21: (นางสาวพนิดา พลนงค์) | J21: (นางสาวพนิดา พลนงค์)
A22: นักจัดการงานทั่วไปปฏิบัติการ | J22: นักจัดการงานทั่วไปปฏิบัติการ
A23: =ขร2!J111 -> โรงพยาบาลสามโคก ประจำเดือน พฤศจิกายน 2568 | J23: =A45 -> โรงพยาบาลสามโคก ประจำเดือน พฤศจิกายน 2568
A24: ชื่อ นางสาวกนกพร มุ่งเจือกลาง ตำแหน่ง พยาบาลวิชาชีพปฏิบัติการ | J24: ชื่อ นายอติวิชญ์ จิรัฐิติชีพ ตำแหน่ง นายแพทย์ชำนาญการ
B26: รายรับ | G26: รายจ่าย | K26: รายรับ | P26: รายจ่าย
B27: เงินเดือน | D27: =ข้าราชการ!E56 -> 0 | G27: ภาษี | H27: 0 | K27: เงินเดือน | M27: 0 | P27: ภาษี | Q27: 0
B28: เงินประจำตำแหน่ง/เท่าตำแหน่ง | D28: 0 | G28: กบข. | H28: 0 | K28: เงินประจำตำแหน่ง/เท่าตำแหน่ง | M28: 0 | P28: กบข. | Q28: 0
B29: เงินเพิ่มพิเศษไม่ทำเวชปฏิบัติ | D29: 0 | G29: สหกรณ์ | H29: 0 | K29: เงินเพิ่มพิเศษไม่ทำเวชปฏิบัติ พ.ย.68 | M29: =ข้าราชการ!G70 -> 0 | P29: สหกรณ์ | Q29: 0
B30: ค่าตอบแทน พตส. | D30: =ข้าราชการ!H58 -> 0 | G30: ฌาปณกิจสงเคราะห์ | H30: =ข้าราชการ!Q58 -> 0 | K30: ค่าตอบแทน พตส. | M30: =ข้าราชการ!H73 -> 0 | P30: ฌาปณกิจสงเคราะห์ | Q30: 0
B31: ค่าตอบแทน ฉ.11 | D31: =ข้าราชการ!I58 -> 0 | G31: ออมสิน | H31: =ข้าราชการ!R58 -> 0 | K31: ค่าตอบแทน ฉ.11 | M31: =ข้าราชการ!I71 -> 0 | P31: ออมสิน | Q31: 0
B32: ค่าตอบแทนนอกเวลาราชการ ต.ค.68 | D32: =ข้าราชการ!J58 -> 0 | G32: กรุงไทย | H32: =ข้าราชการ!S56 -> 0 | K32: ค่าตอบแทนนอกเวลาราชการ ต.ค.68 | M32: =ข้าราชการ!J70 -> 0 | P32: กรุงไทย | Q32: 0
B33: ตกเบิกเงินเดือน | D33: 0 | G33: ไฟฟ้า | H33: =ข้าราชการ!T58 -> 0 | K33: ตกเบิกเงินเดือน | M33: =ข้าราชการ!T70 -> 0 | P33: ไฟฟ้า | Q33: =ข้าราชการ!T71 -> 0
B34: ค่าการศึกษาบุตร | D34: 0 | G34: ประปา | H34: =ข้าราชการ!U56 -> 0 | K34: ค่าการศึกษาบุตร | M34: 0 | P34: ประปา | Q34: =ข้าราชการ!U71 -> 0
B35: ค่ารักษาพยาบาล | D35: =ข้าราชการ!M58 -> 0 | K35: ค่ารักษาพยาบาล | M35: 0
B36: รวมรับ | D36: =SUM(D27:D35) -> 0 | G36: รวมจ่าย | H36: =SUM(H27:H35) -> 0 | K36: รวมรับ | M36: =SUM(M27:M35) -> 0 | P36: รวมจ่าย | Q36: =SUM(Q27:Q35) -> 0
C37: คงเหลือสุทธิ | D37: =D36-H36 -> 0 | F37: บาท | L37: คงเหลือสุทธิ | M37: =M36-Q36 -> 0 | O37: บาท
C38: ="("&BAHTTEXT(D37)&")" -> (ศูนย์บาทถ้วน) | L38: ="("&BAHTTEXT(M37)&")" -> (ศูนย์บาทถ้วน)
B43: (นางสาวพนิดา พลนงค์) | J43: (นางสาวพนิดา พลนงค์)
B44: นักจัดการงานทั่วไปปฏิบัติการ | J44: นักจัดการงานทั่วไปปฏิบัติการ
A45: =ขร1!J177 -> โรงพยาบาลสามโคก ประจำเดือน พฤศจิกายน 2568 | J45: =A67 -> โรงพยาบาลสามโคก ประจำเดือน พฤศจิกายน 2568
A46: ชื่อ นางสาวพรนภา ภูน้ำเย็น ตำแหน่ง พยาบาลวิชาชีพปฏิบัติการ | J46: ชื่อ นายกฤษณพล พิณสุวรรณ์ ตำแหน่ง นายแพทย์ปฏิบัติการ
B48: รายรับ | G48: รายจ่าย | K48: รายรับ | P48: รายจ่าย
B49: เงินเดือน | D49: 0 | G49: ภาษี | H49: =ข้าราชการ!N142 -> 0 | K49: เงินเดือน | M49: 0 | P49: ภาษี | Q49: 0
B50: เงินประจำตำแหน่ง/เท่าตำแหน่ง | D50: 0 | G50: กบข. | H50: =ข้าราชการ!O142 -> 0 | K50: เงินประจำตำแหน่ง/เท่าตำแหน่ง | M50: 0 | P50: กบข. | Q50: 0
B51: เงินเพิ่มพิเศษไม่ทำเวชปฏิบัติ | D51: =ข้าราชการ!G142 -> 0 | G51: สหกรณ์ | H51: =ข้าราชการ!P142 -> 0 | K51: เงินเพิ่มพิเศษไม่ทำเวชปฏิบัติ พ.ย.68 | M51: =ข้าราชการ!G71 -> 0 | P51: สหกรณ์ | Q51: 0
...

Sheet ลจ
A1: =ขร2!J133 -> โรงพยาบาลสามโคก ประจำเดือน พฤศจิกายน 2568
A2: ชื่อ นางวรรณา ถนอมงาม ตำแหน่ง พนักงานพัสดุ
B4: รายรับ | G4: รายจ่าย
B5: เงินเดือน | D5: =ข้าราชการ!E97 -> 0 | G5: ภาษี | H5: =ข้าราชการ!N97 -> 0
B6: เงินประจำตำแหน่ง/เท่าตำแหน่ง | D6: =ข้าราชการ!F97 -> 0 | G6: กบข. | H6: =ข้าราชการ!O97 -> 0
B7: เงินเพิ่มพิเศษไม่ทำเวชปฏิบัติ | D7: =ข้าราชการ!G97 -> 0 | G7: สหกรณ์ | H7: =ข้าราชการ!P97 -> 0
B8: ค่าตอบแทน พตส. | D8: =ข้าราชการ!H97 -> 0 | G8: ฌาปณกิจสงเคราะห์ | H8: =ข้าราชการ!Q97 -> 0
B9: ค่าตอบแทน ฉ.11 ต.ค.68 | D9: =ลจ.ประจำ!I8 -> 10 | G9: ออมสิน | H9: =ข้าราชการ!R97 -> 0
B10: ค่าตอบแทนนอกเวลาราชการ | D10: =ลจ.ประจำ!J8 -> 0 | G10: กรุงไทย | H10: =ข้าราชการ!S97 -> 0
B11: ตกเบิกเงินเดือน | D11: =ลจ.ประจำ!K8 -> 0 | G11: ไฟฟ้า | H11: =ข้าราชการ!T97 -> 0
B12: ค่าการศึกษาบุตร | D12: =ลจ.ประจำ!L8 -> 0 | G12: ประปา | H12: =ข้าราชการ!U97 -> 0
B13: ค่ารักษาพยาบาล | D13: =ลจ.ประจำ!M8 -> 0
B14: รวมรับ | D14: =SUM(D5:D13) -> 10 | G14: รวมจ่าย | H14: =SUM(H5:H13) -> 0
C15: คงเหลือสุทธิ | D15: =D14-H14 -> 10 | F15: บาท
C16: ="("&BAHTTEXT(D15)&")" -> (สิบบาทถ้วน)
A21: (นางสาวพนิดา พลนงค์)
A22: นักจัดการงานทั่วไปปฏิบัติการ

Sheet พนง.ราชการ
A1: =ขร1!A1:I1 -> โรงพยาบาลสามโคก ประจำเดือน พฤศจิกายน 2568
A2: ชื่อ นางสาวสุมาลี เสือเพชร ตำแหน่ง นักวิชาการเงินและบัญชี
B4: รายรับ | G4: รายจ่าย
B5: เงินเดือน | D5: =พนักงาน!E8 -> 0 | G5: ภาษี | H5: =ลจ.ประจำ!N40 -> 0
B6: เงินประจำตำแหน่ง/เท่าตำแหน่ง | D6: =ลจ.ประจำ!F40 -> 0 | G6: ประกันสังคม | H6: =พนักงาน!O8 -> 0
B7: เงินเพิ่มพิเศษไม่ทำเวชปฏิบัติ | D7: =ลจ.ประจำ!G40 -> 0 | G7: สหกรณ์ | H7: =พนักงาน!P8 -> 0
B8: ค่าตอบแทน พตส. | D8: =ลจ.ประจำ!H40 -> 0 | G8: ฌาปณกิจสงเคราะห์ | H8: =พนักงาน!Q8 -> 0
B9: ค่าตอบแทน ฉ.11 ต.ค.68 | D9: =พนักงาน!I8 -> 2 | G9: ออมสิน | H9: =ลจ.ประจำ!R40 -> 0
B10: ค่าตอบแทนนอกเวลาราชการ ต.ค.68 | D10: =พนักงาน!J8 -> 3 | G10: กรุงไทย | H10: =ข้าราชการ!AB85 -> 0
B11: ตกเบิกเงินเดือน | D11: =พนักงาน!K8 -> 0 | G11: ไฟฟ้า | H11: =ลจ.ประจำ!T40 -> 0
B12: ค่าการศึกษาบุตร | D12: =ลจ.ประจำ!L40 -> 0 | G12: ประปา | H12: =ลจ.ประจำ!U40 -> 0
B13: ค่ารักษาพยาบาล | D13: =ลจ.ประจำ!M40 -> 0
B14: รวมรับ | D14: =SUM(D5:D13) -> 5 | G14: รวมจ่าย | H14: =SUM(H5:H13) -> 0
C15: คงเหลือสุทธิ | D15: =D14-H14 -> 5 | F15: บาท
C16: ="("&BAHTTEXT(D15)&")" -> (ห้าบาทถ้วน)
A21: (นางสาวพนิดา พลนงค์)
A22: นักจัดการงานทั่วไปปฏิบัติการ
A23: =พกส.1!J133 -> โรงพยาบาลสามโคก ประจำเดือน พฤศจิกายน 2568
A24: ชื่อ นางสาวพิทยาภรณ์ เจริญสุข ตำแหน่ง แพทย์แผนไทย
B26: รายรับ | G26: รายจ่าย
B27: เงินเดือน | D27: =พนักงาน!E9 -> 0 | G27: ภาษี | H27: 0
B28: เงินประจำตำแหน่ง/เท่าตำแหน่ง | D28: 0 | G28: ประกันสังคม | H28: =พนักงาน!O9 -> 0
B29: เงินเพิ่มพิเศษไม่ทำเวชปฏิบัติ | D29: 0 | G29: สหกรณ์ | H29: =รายเดือน!P8 -> 0
B30: ค่าตอบแทน พตส. | D30: 0 | G30: ฌาปณกิจสงเคราะห์ | H30: 0
B31: ค่าตอบแทน ฉ.11 | D31: =พนักงาน!I9 -> 0 | G31: ออมสิน | H31: =พนักงาน!R9 -> 0
B32: ค่าตอบแทนนอกเวลาราชการ ต.ค.68 | D32: =พนักงาน!J9 -> 0 | G32: กยศ. | H32: =พนักงาน!S9 -> 0
B33: ตกเบิกเงินเดือน | D33: =พนักงาน!K9 -> 0 | G33: ไฟฟ้า | H33: =รายเดือน!T8 -> 0
B34: ค่าการศึกษาบุตร | D34: 0 | G34: ประปา | H34: =รายเดือน!U8 -> 0
B35: ค่ารักษาพยาบาล | D35: 0
B36: รวมรายรับ | D36: =SUM(D27:D35) -> 0 | G36: รวมรายจ่าย | H36: =SUM(H27:H35) -> 0
C37: คงเหลือสุทธิ | D37: =D36-H36 -> 0 | F37: บาท
C38: ="("&BAHTTEXT(D37)&")" -> (ศูนย์บาทถ้วน)
A43: (นางสาวพนิดา พลนงค์)
A44: นักจัดการงานทั่วไปปฏิบัติการ
A45: =พกส.1!J155 -> โรงพยาบาลสามโคก ประจำเดือน พฤศจิกายน 2568
A46: ชื่อ นางสาวณัฐวินีย์ แสงภูติ ตำแหน่ง เภสัชกร
B48: รายรับ | G48: รายจ่าย
B49: เงินเดือน | D49: =พนักงาน!E10 -> 0 | G49: ภาษี | H49: 0
B50: เงินประจำตำแหน่ง/เท่าตำแหน่ง | D50: 0 | G50: ประกันสังคม | H50: =พนักงาน!O10 -> 0
B51: เงินเพิ่มพิเศษไม่ทำเวชปฏิบัติ พ.ย.68 | D51: =พนักงาน!G10 -> 0 | G51: สหกรณ์ | H51: =รายเดือน!P30 -> 0
...

Sheet พกส.1
A1: =ขร1!A1 -> โรงพยาบาลสามโคก ประจำเดือน พฤศจิกายน 2568 | J1: =รว!A1 -> โรงพยาบาลสามโคก ประจำเดือน พฤศจิกายน 2568
A2: ชื่อ นางสาวจรัสศรี แสนศรี ตำแหน่ง พนักงานธุรการ | J2: ชื่อ นางสาววินา จันสด ตำแหน่ง ผู้ช่วยทันตแพทย์
B4: รายรับ | G4: รายจ่าย | K4: รายรับ | P4: รายจ่าย
B5: เงินเดือน | D5: =พกส.!E8 -> 10 | G5: ประกันสังคม | H5: =พกส.!N8 -> 1 | K5: เงินเดือน | M5: =พกส.!E22 -> 0 | P5: ประกันสังคม | Q5: =พกส.!N22 -> 0
B6: เงินประจำตำแหน่ง/เท่าตำแหน่ง | D6: 0 | G6: สหกรณ์ | H6: =พกส.!O8 -> 1 | K6: เงินประจำตำแหน่ง/เท่าตำแหน่ง | M6: 0 | P6: สหกรณ์ | Q6: 1500
B7: เงินเพิ่มพิเศษไม่ทำเวชปฏิบัติ | D7: 0 | G7: ฌาปณกิจสงเคราะห์ | H7: =พกส.!P8 -> 0 | K7: เงินเพิ่มพิเศษไม่ทำเวชปฏิบัติ | M7: 0 | P7: ฌาปณกิจสงเคราะห์ | Q7: 0
B8: ค่าตอบแทน พตส. | D8: 0 | G8: ออมสิน | H8: =พกส.!Q8 -> 0 | K8: ค่าตอบแทน พตส. | M8: 0 | P8: ออมสิน | Q8: 0
B9: ค่าตอบแทน ฉ.11 ต.ค.68 | D9: =พกส.!I8 -> 0 | G9: กสล.พกส. | H9: =พกส.!R8 -> 1 | K9: ค่าตอบแทน ฉ.11 ต.ค.68 | M9: =พกส.!I22 -> 0 | P9: กสล.พกส. | Q9: =พกส.!R22 -> 0
B10: ค่าตอบแทนนอกเวลาราชการ ต.ค.68 | D10: =พกส.!J8 -> 0 | G10: กรุงไทย | H10: =ข้าราชการ!S117 -> 0 | K10: ค่าตอบแทนนอกเวลาราชการ | M10: =พกส.!J22 -> 0 | P10: กรุงไทย | Q10: =ข้าราชการ!AB117 -> 0
B11: ตกเบิกเงินเดือน ต.ค.68 | D11: =พกส.!L8 -> 3 | G11: กยศ. | H11: =ข้าราชการ!S118 -> 0 | K11: ตกเบิกเงินเดือน ต.ค.68 | M11: =พกส.!L22 -> 0 | P11: กยศ. | Q11: =ข้าราชการ!AC117 -> 0
B12: ค่าการศึกษาบุตร | D12: 0 | G12: ไฟฟ้า | H12: =พกส.!U8 -> 0 | K12: เงินเดือนรายวัน | M12: 0 | P12: ไฟฟ้า | Q12: =ข้าราชการ!AC118 -> 0
B13: ค่ารักษาพยาบาล | D13: 0 | G13: ประปา | H13: =พกส.!V8 -> 0 | K13: ค่ารักษาพยาบาล | M13: 0 | P13: ประปา
B14: รวมรายรับ | D14: =SUM(D5:D13) -> 13 | G14: รวมรายจ่าย | H14: =SUM(H5:H13) -> 3 | K14: รวมรับ | M14: =SUM(M5:M13) -> 0 | P14: รวมจ่าย | Q14: =SUM(Q5:Q13) -> 1500
C15: คงเหลือสุทธิ | D15: =D14-H14 -> 10 | F15: บาท | L15: คงเหลือสุทธิ | M15: =M14-Q14 -> -1500 | O15: บาท
C16: ="("&BAHTTEXT(D15)&")" -> (สิบบาทถ้วน) | L16: ="("&BAHTTEXT(M15)&")" -> (ลบหนึ่งพันห้าร้อยบาทถ้วน)
A21: (นางสาวพนิดา พลนงค์) | J21: (นางสาวพนิดา พลนงค์)
A22: นักจัดการงานทั่วไปปฏิบัติการ | J22: นักจัดการงานทั่วไปปฏิบัติการ
A23: =พกส.1!A1 -> โรงพยาบาลสามโคก ประจำเดือน พฤศจิกายน 2568 | J23: =A1 -> โรงพยาบาลสามโคก ประจำเดือน พฤศจิกายน 2568
A24: ชื่อ นางสาวเบญจวรรณ สุขชูศรี ตำแหน่ง พนักงานช่วยเหลือคนไข้ | J24: ชื่อ นางสาวศศิกร ไตลังคะ ตำแหน่ง พนักงานช่วยเหลือคนไข้
B26: รายรับ | G26: รายจ่าย | K26: รายรับ | P26: รายจ่าย
B27: เงินเดือน | D27: =พกส.!E9 -> 10 | G27: ประกันสังคม | H27: =พกส.!N9 -> 0 | K27: เงินเดือน | M27: =พกส.!E23 -> 0 | P27: ประกันสังคม | Q27: =พกส.!N23 -> 0
B28: เงินประจำตำแหน่ง/เท่าตำแหน่ง | D28: 0 | G28: สหกรณ์ | H28: 0 | K28: เงินประจำตำแหน่ง/เท่าตำแหน่ง | M28: 0 | P28: สหกรณ์ | Q28: =พกส.!O23 -> 0
B29: เงินเพิ่มพิเศษไม่ทำเวชปฏิบัติ | D29: 0 | G29: ฌาปณกิจสงเคราะห์ | H29: =พกส.!P9 -> 1 | K29: เงินเพิ่มพิเศษไม่ทำเวชปฏิบัติ | M29: 0 | P29: ฌาปณกิจสงเคราะห์ | Q29: =พกส.!P23 -> 0
B30: ค่าตอบแทน พตส. | D30: 0 | G30: ออมสิน | H30: 0 | K30: ค่าตอบแทน พตส. | M30: 0 | P30: ออมสิน | Q30: 0
B31: ค่าตอบแทน ฉ.11 ต.ค.68 | D31: =พกส.!I9 -> 0 | G31: กสล.พกส. | H31: =พกส.!R9 -> 0 | K31: ค่าตอบแทน ฉ.11 ต.ค.68 | M31: =พกส.!I23 -> 0 | P31: กสล.พกส. | Q31: =พกส.!R23 -> 0
B32: ค่าตอบแทนนอกเวลาราชการ ต.ค.68 | D32: =พกส.!J9 -> 0 | G32: กรุงไทย | H32: 0 | K32: ค่าตอบแทนนอกเวลาราชการ ต.ค.68 | M32: =พกส.!J23 -> 0 | P32: กรุงไทย | Q32: 0
B33: ค่าตอบแทนพิเศษเต็มขั้น ต.ค.-พ.ย.68 | D33: =พกส.!K9 -> 500 | G33: กยศ. | H33: 0 | K33: ตกเบิกเงินเดือน ต.ค.68 | M33: =พกส.!L23 -> 0 | P33: กยศ. | Q33: 0
B34: ตกเบิกเงินเดือน | D34: =พกส.!L9 -> 0 | G34: ไฟฟ้า | H34: 0 | K34: เงินเดือนรายวัน | M34: 0 | P34: ไฟฟ้า | Q34: =พกส.!U23 -> 0
B35: ค่ารักษาพยาบาล | D35: =พกส.!M9 -> 0 | G35: ประปา | H35: 0 | K35: ค่ารักษาพยาบาล | M35: 0 | P35: ประปา | Q35: =พกส.!V23 -> 0
B36: รวมรายรับ | D36: =SUM(D27:D35) -> 510 | G36: รวมรายจ่าย | H36: =SUM(H27:H35) -> 1 | K36: รวมรับ | M36: =SUM(M27:M35) -> 0 | P36: รวมจ่าย | Q36: =SUM(Q27:Q35) -> 0
C37: คงเหลือสุทธิ | D37: =D36-H36 -> 509 | F37: บาท | L37: คงเหลือสุทธิ | M37: =M36-Q36 -> 0 | O37: บาท
C38: ="("&BAHTTEXT(D37)&")" -> (ห้าร้อยเก้าบาทถ้วน) | L38: ="("&BAHTTEXT(M37)&")" -> (ศูนย์บาทถ้วน)
A43: (นางสาวพนิดา พลนงค์) | J43: (นางสาวพนิดา พลนงค์)
A44: นักจัดการงานทั่วไปปฏิบัติการ | J44: นักจัดการงานทั่วไปปฏิบัติการ
A45: =A1 -> โรงพยาบาลสามโคก ประจำเดือน พฤศจิกายน 2568 | J45: =รว!A1 -> โรงพยาบาลสามโคก ประจำเดือน พฤศจิกายน 2568
A46: ชื่อ นายสัญญา แย้มดี ตำแหน่ง พนักงานช่วยเหลือคนไข้ | J46: ชื่อ นางสาวกรรณิการ์ แสงมีคุณ ตำแหน่ง พนักงานบริการ
B48: รายรับ | G48: รายจ่าย | K48: รายรับ | P48: รายจ่าย
B49: เงินเดือน | D49: =พกส.!E10 -> 10 | G49: ประกันสังคม | H49: =พกส.!N10 -> 0 | K49: เงินเดือน | M49: =พกส.!E24 -> 0 | P49: ประกันสังคม | Q49: =พกส.!N24 -> 0
B50: เงินประจำตำแหน่ง/เท่าตำแหน่ง | D50: 0 | G50: สหกรณ์ | H50: =พกส.!O10 -> 0 | K50: เงินประจำตำแหน่ง/เท่าตำแหน่ง | M50: 0 | P50: สหกรณ์ | Q50: 0
B51: เงินเพิ่มพิเศษไม่ทำเวชปฏิบัติ | D51: 0 | G51: ฌาปณกิจสงเคราะห์ | H51: =พกส.!P10 -> 0 | K51: เงินเพิ่มพิเศษไม่ทำเวชปฏิบัติ | M51: 0 | P51: ฌาปณกิจสงเคราะห์ | Q51: =พกส.!P24 -> 0
...

Sheet พกส.1 (2)
A1: =ขร1!A1 -> โรงพยาบาลสามโคก ประจำเดือน พฤศจิกายน 2568
A2: ชื่อ นายอัฐพล วงค์คำดี ตำแหน่ง พนักงานขับรถยนต์
B4: รายรับ | G4: รายจ่าย
B5: เงินเดือน | D5: =พกส.!E38 -> 0 | G5: ประกันสังคม | H5: =พกส.!N38 -> 0
B6: เงินประจำตำแหน่ง/เท่าตำแหน่ง | D6: 0 | G6: สหกรณ์ | H6: 0
B7: เงินเพิ่มพิเศษไม่ทำเวชปฏิบัติ | D7: 0 | G7: ฌาปณกิจสงเคราะห์ | H7: 0
B8: ค่าตอบแทน พตส. | D8: 0 | G8: ออมสิน | H8: 0
B9: ค่าตอบแทน ฉ.11 ต.ค.68 | D9: =พกส.!I38 -> 0 | G9: กสล.พกส. | H9: =พกส.!Q8 -> 0
B10: ค่าตอบแทนนอกเวลาราชการ ต.ค.68 | D10: =พกส.!J38 -> 0 | G10: กรุงไทย | H10: 0
B11: ตกเบิกเงินเดือน | D11: 0 | G11: กยศ. | H11: =พกส.!T38 -> 0
B12: ค่าการศึกษาบุตร | D12: 0 | G12: ไฟฟ้า | H12: =พกส.!U38 -> 0
B13: ค่ารักษาพยาบาล | D13: 0 | G13: ประปา | H13: =พกส.!V38 -> 0
B14: รวมรายรับ | D14: =SUM(D5:D13) -> 0 | G14: รวมรายจ่าย | H14: =SUM(H5:H13) -> 0
C15: คงเหลือสุทธิ | D15: =D14-H14 -> 0 | F15: บาท
C16: ="("&BAHTTEXT(D15)&")" -> (ศูนย์บาทถ้วน)
A21: (นางสาวพนิดา พลนงค์)
A22: นักจัดการงานทั่วไปปฏิบัติการ
A23: =ขร1!A23 -> โรงพยาบาลสามโคก ประจำเดือน พฤศจิกายน 2568
A24: ชื่อ นางสาววรรณวิสา ธนะจักร์ ตำแหน่ง พนักงานช่วยเหลือคนไข้
B26: รายรับ | G26: รายจ่าย
B27: เงินเดือน | D27: =พกส.!E39 -> 0 | G27: ประกันสังคม | H27: =พกส.!N39 -> 0
B28: เงินประจำตำแหน่ง/เท่าตำแหน่ง | D28: 0 | G28: สหกรณ์ | H28: 0
B29: เงินเพิ่มพิเศษไม่ทำเวชปฏิบัติ | D29: 0 | G29: ฌาปณกิจสงเคราะห์ | H29: 0
B30: ค่าตอบแทน พตส. | D30: 0 | G30: ออมสิน | H30: 0
B31: ค่าตอบแทน ฉ.11 ต.ค.68 | D31: =พกส.!I39 -> 0 | G31: กสล.พกส. | H31: =พกส.!Q30 -> 0
B32: ค่าตอบแทนนอกเวลาราชการ ต.ค.68 | D32: =พกส.!J39 -> 0 | G32: กรุงไทย | H32: 0
B33: ตกเบิกเงินเดือน | D33: 0 | G33: กยศ. | H33: =พกส.!T60 -> 0
B34: ค่าการศึกษาบุตร | D34: 0 | G34: ไฟฟ้า | H34: =พกส.!U39 -> 0
B35: ค่ารักษาพยาบาล | D35: 0 | G35: ประปา | H35: =พกส.!V39 -> 0
B36: รวมรายรับ | D36: =SUM(D27:D35) -> 0 | G36: รวมรายจ่าย | H36: =SUM(H27:H35) -> 0
C37: คงเหลือสุทธิ | D37: =D36-H36 -> 0 | F37: บาท
C38: ="("&BAHTTEXT(D37)&")" -> (ศูนย์บาทถ้วน)
A43: (นางสาวพนิดา พลนงค์)
A44: นักจัดการงานทั่วไปปฏิบัติการ
A45: =ขร1!A45 -> โรงพยาบาลสามโคก ประจำเดือน พฤศจิกายน 2568
A46: ชื่อ นางสาวศิริลักษณ์ ชมภูนุช ตำแหน่ง พนักงานช่วยเหลือคนไข้
B48: รายรับ | G48: รายจ่าย
B49: เงินเดือน | D49: =พกส.!E40 -> 0 | G49: ประกันสังคม | H49: =พกส.!N40 -> 0
B50: เงินประจำตำแหน่ง/เท่าตำแหน่ง | D50: 0 | G50: สหกรณ์ | H50: 0
B51: เงินเพิ่มพิเศษไม่ทำเวชปฏิบัติ | D51: 0 | G51: ฌาปณกิจสงเคราะห์ | H51: 0
...

Sheet รด.1
A1: =พกส.1!A111 -> โรงพยาบาลสามโคก ประจำเดือน พฤศจิกายน 2568
A2: ชื่อ นางสาวปพิชญา อังกีรัตน์ ตำแหน่ง นักวิชาการสาธารณสุข
B4: รายรับ | G4: รายจ่าย
B5: เงินเดือน | D5: =รายเดือน!E8 -> 0 | G5: ภาษี | H5: 0
B6: เงินประจำตำแหน่ง/เท่าตำแหน่ง | D6: 0 | G6: ประกันสังคม | H6: =รายเดือน!O8 -> 0
B7: เงินเพิ่มพิเศษไม่ทำเวชปฏิบัติ | D7: 0 | G7: สหกรณ์ | H7: 0
B8: ค่าตอบแทน พตส. | D8: 0 | G8: ฌาปณกิจสงเคราะห์ | H8: 0
B9: ค่าตอบแทน ฉ.11 | D9: =รายเดือน!I8 -> 0 | G9: ออมสิน | H9: 0
B10: ค่าตอบแทนนอกเวลาราชการ | D10: =รายเดือน!J8 -> 0 | G10: ไฟฟ้า | H10: 0
B11: ตกเบิกเงินเดือน | D11: =รายเดือน!K8 -> 0 | G11: ประปา | H11: 0
B12: ค่าการศึกษาบุตร | D12: 0
B13: ค่ารักษาพยาบาล | D13: 0
B14: รวมรายรับ | D14: =SUM(D5:D13) -> 0 | G14: รวมรายจ่าย | H14: =SUM(H5:H13) -> 0
C15: คงเหลือสุทธิ | D15: =D14-H14 -> 0 | F15: บาท
C16: ="("&BAHTTEXT(D15)&")" -> (ศูนย์บาทถ้วน)
A21: (นางสาวพนิดา พลนงค์)
A22: นักจัดการงานทั่วไปปฏิบัติการ
A23: =พนง.ราชการ!A23 -> โรงพยาบาลสามโคก ประจำเดือน พฤศจิกายน 2568
A24: ชื่อ นางสาวกัลยารัตน์ มหามนต์ ตำแหน่ง นักวิชาการสาธารณสุข
B26: รายรับ | G26: รายจ่าย
B27: เงินเดือน | D27: =รายเดือน!E9 -> 0 | G27: ภาษี | H27: 0
B28: เงินประจำตำแหน่ง/เท่าตำแหน่ง | D28: 0 | G28: ประกันสังคม | H28: =รายเดือน!O9 -> 0
B29: เงินเพิ่มพิเศษไม่ทำเวชปฏิบัติ | D29: 0 | G29: สหกรณ์ | H29: 0
B30: ค่าตอบแทน พตส. | D30: =รายเดือน!H9 -> 0 | G30: ฌาปณกิจสงเคราะห์ | H30: 0
B31: ค่าตอบแทน ฉ.11 | D31: =รายเดือน!I9 -> 0 | G31: ออมสิน | H31: 0
B32: ค่าตอบแทนนอกเวลาราชการ | D32: =รายเดือน!J9 -> 0 | G32: กยศ. | H32: =รายเดือน!S9 -> 0
B33: ตกเบิกเงินเดือน | D33: =รายเดือน!K11 -> 0 | G33: ไฟฟ้า | H33: =รายเดือน!T9 -> 0
B34: ค่าการศึกษาบุตร | D34: 0 | G34: ประปา | H34: =รายเดือน!U9 -> 0
B35: ค่ารักษาพยาบาล | D35: 0
B36: รวมรายรับ | D36: =SUM(D27:D35) -> 0 | G36: รวมรายจ่าย | H36: =SUM(H27:H35) -> 0
C37: คงเหลือสุทธิ | D37: =D36-H36 -> 0 | F37: บาท
C38: ="("&BAHTTEXT(D37)&")" -> (ศูนย์บาทถ้วน)
A43: (นางสาวพนิดา พลนงค์)
A44: นักจัดการงานทั่วไปปฏิบัติการ
A45: =A1 -> โรงพยาบาลสามโคก ประจำเดือน พฤศจิกายน 2568
A46: ชื่อ นางสาววศิกา เจริญวุฒิกุล ตำแหน่ง แพทย์แผนไทย
B48: รายรับ | G48: รายจ่าย
B49: เงินเดือน | D49: =รายเดือน!E10 -> 0 | G49: ภาษี | H49: 0
B50: เงินประจำตำแหน่ง/เท่าตำแหน่ง | D50: 0 | G50: ประกันสังคม | H50: =รายเดือน!O10 -> 0
B51: เงินเพิ่มพิเศษไม่ทำเวชปฏิบัติ | D51: 0 | G51: สหกรณ์ | H51: 0
...

Sheet รว
A1: =ขร1!A1:I1 -> โรงพยาบาลสามโคก ประจำเดือน พฤศจิกายน 2568 | J1: =รว!A23 -> โรงพยาบาลสามโคก ประจำเดือน พฤศจิกายน 2568
A2: ชื่อ นางประเสริฐศรี พวงผกา ตำแหน่ง พนักงานซักฟอก | J2: ชื่อ นางสาวสุนารี เกิดทวี ตำแหน่ง เจ้าพนักงานการเงินและบัญชี
B4: รายรับ | G4: รายจ่าย | K4: รายรับ | P4: รายจ่าย
B5: เงินเดือน | D5: =รายวัน!E8 -> 0 | G5: ภาษี | H5: 0 | K5: เงินเดือน | M5: =รายวัน!E20 -> 0 | P5: ภาษี | Q5: 0
B6: เงินประจำตำแหน่ง/เท่าตำแหน่ง | D6: 0 | G6: ประกันสังคม | H6: =รายวัน!O8 -> 0 | K6: เงินประจำตำแหน่ง/เท่าตำแหน่ง | M6: 0 | P6: ประกันสังคม | Q6: =รายวัน!O20 -> 0
B7: เงินเพิ่มพิเศษไม่ทำเวชปฏิบัติ | D7: 0 | G7: สหกรณ์ | H7: 0 | K7: เงินเพิ่มพิเศษไม่ทำเวชปฏิบัติ | M7: 0 | P7: สหกรณ์ | Q7: 0
B8: ค่าตอบแทน พตส. | D8: 0 | G8: ฌาปณกิจสงเคราะห์ | H8: 0 | K8: ค่าตอบแทน พตส. | M8: =รายวัน!H20 -> 0 | P8: ฌาปณกิจสงเคราะห์ | Q8: 0
B9: ค่าตอบแทน ฉ.11 ต.ค.68 | D9: =รายวัน!I8 -> 0 | G9: ออมสิน | H9: 0 | K9: ค่าตอบแทน ฉ.11 ต.ค.68 | M9: =รายวัน!I20 -> 0 | P9: ออมสิน | Q9: 0
B10: ค่าตอบแทนนอกเวลาราชการ ต.ค.68 | D10: =รายวัน!J8 -> 0 | G10: ไฟฟ้า | H10: 0 | K10: ค่าตอบแทนนอกเวลาราชการ ต.ค.68 | M10: =รายวัน!J20 -> 0 | P10: กรุงไทย | Q10: 0
